Workbook

Sheet Dashboard
A1: Habit Tracker Dashboard
A3: Year | E3: Good points | I3: Bad penalty
A4: =Setup!$B$3 | E4: =Setup!$B$4 | I4: =Setup!$B$5
A6: Net score (YTD) | E6: Good done (YTD) | I6: Bad happened (YTD)
A7: =SUM(Jan!$AM$33,Feb!$AM$33,Mar!$AM$33,Apr!$AM$33,May!$AM$33,Jun!$AM$33,Jul!$AM$33,Aug!$AM$33,Sep!$AM$33,Oct!$AM$33,Nov!$AM$33,Dec!$AM$33) | E7: =SUM(Jan!$AM$31,Feb!$AM$31,Mar!$AM$31,Apr!$AM$31,May!$AM$31,Jun!$AM$31,Jul!$AM$31,Aug!$AM$31,Sep!$AM$31,Oct!$AM$31,Nov!$AM$31,Dec!$AM$31) | I7: =SUM(Jan!$AM$32,Feb!$AM$32,Mar!$AM$32,Apr!$AM$32,May!$AM$32,Jun!$AM$32,Jul!$AM$32,Aug!$AM$32,Sep!$AM$32,Oct!$AM$32,Nov!$AM$32,Dec!$AM$32)
A10: Month | B10: Good done | C10: Bad happened | D10: Net score | E10: Avg completion (Good) | G10: Cumulative net
A11: Jan | B11: =Jan!$AM$31 | C11: =Jan!$AM$32 | D11: =Jan!$AM$33 | E11: =Jan!$AM$34 | G11: =D11
A12: Feb | B12: =Feb!$AM$31 | C12: =Feb!$AM$32 | D12: =Feb!$AM$33 | E12: =Feb!$AM$34 | G12: =G11+D12
A13: Mar | B13: =Mar!$AM$31 | C13: =Mar!$AM$32 | D13: =Mar!$AM$33 | E13: =Mar!$AM$34 | G13: =G12+D13
A14: Apr | B14: =Apr!$AM$31 | C14: =Apr!$AM$32 | D14: =Apr!$AM$33 | E14: =Apr!$AM$34 | G14: =G13+D14
A15: May | B15: =May!$AM$31 | C15: =May!$AM$32 | D15: =May!$AM$33 | E15: =May!$AM$34 | G15: =G14+D15
A16: Jun | B16: =Jun!$AM$31 | C16: =Jun!$AM$32 | D16: =Jun!$AM$33 | E16: =Jun!$AM$34 | G16: =G15+D16
A17: Jul | B17: =Jul!$AM$31 | C17: =Jul!$AM$32 | D17: =Jul!$AM$33 | E17: =Jul!$AM$34 | G17: =G16+D17
A18: Aug | B18: =Aug!$AM$31 | C18: =Aug!$AM$32 | D18: =Aug!$AM$33 | E18: =Aug!$AM$34 | G18: =G17+D18
A19: Sep | B19: =Sep!$AM$31 | C19: =Sep!$AM$32 | D19: =Sep!$AM$33 | E19: =Sep!$AM$34 | G19: =G18+D19
A20: Oct | B20: =Oct!$AM$31 | C20: =Oct!$AM$32 | D20: =Oct!$AM$33 | E20: =Oct!$AM$34 | G20: =G19+D20
A21: Nov | B21: =Nov!$AM$31 | C21: =Nov!$AM$32 | D21: =Nov!$AM$33 | E21: =Nov!$AM$34 | G21: =G20+D21
A22: Dec | B22: =Dec!$AM$31 | C22: =Dec!$AM$32 | D22: =Dec!$AM$33 | E22: =Dec!$AM$34 | G22: =G21+D22

Sheet Setup
A1: Habit Tracker Dashboard (No Macros) — Setup
A3: Year | B3: 2026 | G3: Tip:
A4: Good habit points | B4: 1 | G4: • Add habits below. Set Active=1 to include in dashboards.
A5: Bad habit penalty (negative) | B5: -4 | G5: • In month sheets, enter 1 when you did a habit, 0 when you didn't.
G6: • Bad habits: enter 1 when they happened (penalty applies).
A8: Habit | B8: Type (Good/Bad) | C8: Category | D8: Active (1/0) | E8: Points
A9: Exercise | B9: Good | C9: Health | D9: 1 | E9: =IF($B9="Good",$B$4,IF($B9="Bad",$B$5,0))
A10: Deep Work (2h) | B10: Good | C10: Work | D10: 1 | E10: =IF($B10="Good",$B$4,IF($B10="Bad",$B$5,0))
A11: Junk Food | B11: Bad | C11: Health | D11: 1 | E11: =IF($B11="Good",$B$4,IF($B11="Bad",$B$5,0))
A12: Social Media > 1h | B12: Bad | C12: Distraction | D12: 1 | E12: =IF($B12="Good",$B$4,IF($B12="Bad",$B$5,0))
D13: 0 | E13: =IF($B13="Good",$B$4,IF($B13="Bad",$B$5,0))
D14: 0 | E14: =IF($B14="Good",$B$4,IF($B14="Bad",$B$5,0))
D15: 0 | E15: =IF($B15="Good",$B$4,IF($B15="Bad",$B$5,0))
D16: 0 | E16: =IF($B16="Good",$B$4,IF($B16="Bad",$B$5,0))
D17: 0 | E17: =IF($B17="Good",$B$4,IF($B17="Bad",$B$5,0))
D18: 0 | E18: =IF($B18="Good",$B$4,IF($B18="Bad",$B$5,0))
D19: 0 | E19: =IF($B19="Good",$B$4,IF($B19="Bad",$B$5,0))
D20: 0 | E20: =IF($B20="Good",$B$4,IF($B20="Bad",$B$5,0))
D21: 0 | E21: =IF($B21="Good",$B$4,IF($B21="Bad",$B$5,0))
D22: 0 | E22: =IF($B22="Good",$B$4,IF($B22="Bad",$B$5,0))
D23: 0 | E23: =IF($B23="Good",$B$4,IF($B23="Bad",$B$5,0))
D24: 0 | E24: =IF($B24="Good",$B$4,IF($B24="Bad",$B$5,0))
... D28: 0 | E28: =IF($B28="Good",$B$4,IF($B28="Bad",$B$5,0))

Sheet Jan
A1: Jan Habit Tracker
A2: Year: | B2: =Setup!$B$3 | C2: Month: | D2: Jan
A3: Days in month: | B3: =DAY(EOMONTH(DATE(Setup!$B$3,1,1),0))
E5: =TEXT(DATE(Setup!$B$3,1,1),"ddd") | F5: =TEXT(DATE(Setup!$B$3,1,2),"ddd") | G5: =TEXT(DATE(Setup!$B$3,1,3),"ddd") | H5: =TEXT(DATE(Setup!$B$3,1,4),"ddd") | I5: =TEXT(DATE(Setup!$B$3,1,5),"ddd") | J5: =TEXT(DATE(Setup!$B$3,1,6),"ddd") | K5: =TEXT(DATE(Setup!$B$3,1,7),"ddd") | L5: =TEXT(DATE(Setup!$B$3,1,8),"ddd") | M5: =TEXT(DATE(Setup!$B$3,1,9),"ddd") | N5: =TEXT(DATE(Setup!$B$3,1,10),"ddd") | O5: =TEXT(DATE(Setup!$B$3,1,11),"ddd") | P5: =TEXT(DATE(Setup!$B$3,1,12),"ddd") | Q5: =TEXT(DATE(Setup!$B$3,1,13),"ddd") | R5: =TEXT(DATE(Setup!$B$3,1,14),"ddd") | S5: =TEXT(DATE(Setup!$B$3,1,15),"ddd") | T5: =TEXT(DATE(Setup!$B$3,1,16),"ddd") | U5: =TEXT(DATE(Setup!$B$3,1,17),"ddd") | V5: =TEXT(DATE(Setup!$B$3,1,18),"ddd") | W5: =TEXT(DATE(Setup!$B$3,1,19),"ddd") | X5: =TEXT(DATE(Setup!$B$3,1,20),"ddd") | Y5: =TEXT(DATE(Setup!$B$3,1,21),"ddd") | Z5: =TEXT(DATE(Setup!$B$3,1,22),"ddd") | AA5: =TEXT(DATE(Setup!$B$3,1,23),"ddd") | AB5: =TEXT(DATE(Setup!$B$3,1,24),"ddd") | AC5: =TEXT(DATE(Setup!$B$3,1,25),"ddd") | AD5: =TEXT(DATE(Setup!$B$3,1,26),"ddd") | AE5: =TEXT(DATE(Setup!$B$3,1,27),"ddd") | AF5: =TEXT(DATE(Setup!$B$3,1,28),"ddd") | AG5: =TEXT(DATE(Setup!$B$3,1,29),"ddd") | AH5: =TEXT(DATE(Setup!$B$3,1,30),"ddd") | AI5: =TEXT(DATE(Setup!$B$3,1,31),"ddd")
A6: Active | B6: Habit | C6: Type | D6: Points | E6: 1 | F6: 2 | G6: 3 | H6: 4 | I6: 5 | J6: 6 | K6: 7 | L6: 8 | M6: 9 | N6: 10 | O6: 11 | P6: 12 | Q6: 13 | R6: 14 | S6: 15 | T6: 16 | U6: 17 | V6: 18 | W6: 19 | X6: 20 | Y6: 21 | Z6: 22 | AA6: 23 | AB6: 24 | AC6: 25 | AD6: 26 | AE6: 27 | AF6: 28 | AG6: 29 | AH6: 30 | AI6: 31 | AJ6: Total
A7: =Setup!D9 | B7: =Setup!A9 | C7: =Setup!B9 | D7: =Setup!E9 | AJ7: =IF($A7=1,SUMPRODUCT(($E$6:$AI$6<=$B$3)*(E7:AI7)),"")
A8: =Setup!D10 | B8: =Setup!A10 | C8: =Setup!B10 | D8: =Setup!E10 | AJ8: =IF($A8=1,SUMPRODUCT(($E$6:$AI$6<=$B$3)*(E8:AI8)),"")
A9: =Setup!D11 | B9: =Setup!A11 | C9: =Setup!B11 | D9: =Setup!E11 | AJ9: =IF($A9=1,SUMPRODUCT(($E$6:$AI$6<=$B$3)*(E9:AI9)),"")
A10: =Setup!D12 | B10: =Setup!A12 | C10: =Setup!B12 | D10: =Setup!E12 | AJ10: =IF($A10=1,SUMPRODUCT(($E$6:$AI$6<=$B$3)*(E10:AI10)),"")
A11: =Setup!D13 | B11: =Setup!A13 | C11: =Setup!B13 | D11: =Setup!E13 | AJ11: =IF($A11=1,SUMPRODUCT(($E$6:$AI$6<=$B$3)*(E11:AI11)),"")
A12: =Setup!D14 | B12: =Setup!A14 | C12: =Setup!B14 | D12: =Setup!E14 | AJ12: =IF($A12=1,SUMPRODUCT(($E$6:$AI$6<=$B$3)*(E12:AI12)),"")
A13: =Setup!D15 | B13: =Setup!A15 | C13: =Setup!B15 | D13: =Setup!E15 | AJ13: =IF($A13=1,SUMPRODUCT(($E$6:$AI$6<=$B$3)*(E13:AI13)),"")
A14: =Setup!D16 | B14: =Setup!A16 | C14: =Setup!B16 | D14: =Setup!E16 | AJ14: =IF($A14=1,SUMPRODUCT(($E$6:$AI$6<=$B$3)*(E14:AI14)),"")
A15: =Setup!D17 | B15: =Setup!A17 | C15: =Setup!B17 | D15: =Setup!E17 | AJ15: =IF($A15=1,SUMPRODUCT(($E$6:$AI$6<=$B$3)*(E15:AI15)),"")
A16: =Setup!D18 | B16: =Setup!A18 | C16: =Setup!B18 | D16: =Setup!E18 | AJ16: =IF($A16=1,SUMPRODUCT(($E$6:$AI$6<=$B$3)*(E16:AI16)),"")
A17: =Setup!D19 | B17: =Setup!A19 | C17: =Setup!B19 | D17: =Setup!E19 | AJ17: =IF($A17=1,SUMPRODUCT(($E$6:$AI$6<=$B$3)*(E17:AI17)),"")
A18: =Setup!D20 | B18: =Setup!A20 | C18: =Setup!B20 | D18: =Setup!E20 | AJ18: =IF($A18=1,SUMPRODUCT(($E$6:$AI$6<=$B$3)*(E18:AI18)),"")
... A26: =Setup!D28 | B26: =Setup!A28 | C26: =Setup!B28 | D26: =Setup!E28 | AJ26: =IF($A26=1,SUMPRODUCT(($E$6:$AI$6<=$B$3)*(E26:AI26)),"")
A29: Daily summary
A30: Good habits done | E30: =SUMPRODUCT(($A$7:$A$26=1)*($C$7:$C$26="Good")*(E7:E26)) | F30: =SUMPRODUCT(($A$7:$A$26=1)*($C$7:$C$26="Good")*(F7:F26)) | G30: =SUMPRODUCT(($A$7:$A$26=1)*($C$7:$C$26="Good")*(G7:G26)) | H30: =SUMPRODUCT(($A$7:$A$26=1)*($C$7:$C$26="Good")*(H7:H26)) | I30: =SUMPRODUCT(($A$7:$A$26=1)*($C$7:$C$26="Good")*(I7:I26)) | J30: =SUMPRODUCT(($A$7:$A$26=1)*($C$7:$C$26="Good")*(J7:J26)) | K30: =SUMPRODUCT(($A$7:$A$26=1)*($C$7:$C$26="Good")*(K7:K26)) | L30: =SUMPRODUCT(($A$7:$A$26=1)*($C$7:$C$26="Good")*(L7:L26)) | ... AI30: =SUMPRODUCT(($A$7:$A$26=1)*($C$7:$C$26="Good")*(AI7:AI26)) | AL30: Monthly totals
A31: Bad habits happened | E31: =SUMPRODUCT(($A$7:$A$26=1)*($C$7:$C$26="Bad")*(E7:E26)) | F31: =SUMPRODUCT(($A$7:$A$26=1)*($C$7:$C$26="Bad")*(F7:F26)) | G31: =SUMPRODUCT(($A$7:$A$26=1)*($C$7:$C$26="Bad")*(G7:G26)) | H31: =SUMPRODUCT(($A$7:$A$26=1)*($C$7:$C$26="Bad")*(H7:H26)) | I31: =SUMPRODUCT(($A$7:$A$26=1)*($C$7:$C$26="Bad")*(I7:I26)) | J31: =SUMPRODUCT(($A$7:$A$26=1)*($C$7:$C$26="Bad")*(J7:J26)) | K31: =SUMPRODUCT(($A$7:$A$26=1)*($C$7:$C$26="Bad")*(K7:K26)) | L31: =SUMPRODUCT(($A$7:$A$26=1)*($C$7:$C$26="Bad")*(L7:L26)) | ... AI31: =SUMPRODUCT(($A$7:$A$26=1)*($C$7:$C$26="Bad")*(AI7:AI26)) | AL31: Good done | AM31: =SUMPRODUCT(($E$6:$AI$6<=$B$3)*(E30:AI30))
A32: Net score | E32: =SUMPRODUCT(($A$7:$A$26=1)*($D$7:$D$26)*(E7:E26)) | F32: =SUMPRODUCT(($A$7:$A$26=1)*($D$7:$D$26)*(F7:F26)) | G32: =SUMPRODUCT(($A$7:$A$26=1)*($D$7:$D$26)*(G7:G26)) | H32: =SUMPRODUCT(($A$7:$A$26=1)*($D$7:$D$26)*(H7:H26)) | I32: =SUMPRODUCT(($A$7:$A$26=1)*($D$7:$D$26)*(I7:I26)) | J32: =SUMPRODUCT(($A$7:$A$26=1)*($D$7:$D$26)*(J7:J26)) | K32: =SUMPRODUCT(($A$7:$A$26=1)*($D$7:$D$26)*(K7:K26)) | L32: =SUMPRODUCT(($A$7:$A$26=1)*($D$7:$D$26)*(L7:L26)) | ... AI32: =SUMPRODUCT(($A$7:$A$26=1)*($D$7:$D$26)*(AI7:AI26)) | AL32: Bad happened | AM32: =SUMPRODUCT(($E$6:$AI$6<=$B$3)*(E31:AI31))
A33: Completion % (Good only) | E33: =IF(SUMPRODUCT(($A$7:$A$26=1)*($C$7:$C$26="Good"))=0,"",SUMPRODUCT(($A$7:$A$26=1)*($C$7:$C$26="Good")*(E7:E26))/SUMPRODUCT(($A$7:$A$26=1)*($C$7:$C$26="Good"))) | F33: =IF(SUMPRODUCT(($A$7:$A$26=1)*($C$7:$C$26="Good"))=0,"",SUMPRODUCT(($A$7:$A$26=1)*($C$7:$C$26="Good")*(F7:F26))/SUMPRODUCT(($A$7:$A$26=1)*($C$7:$C$26="Good"))) | G33: =IF(SUMPRODUCT(($A$7:$A$26=1)*($C$7:$C$26="Good"))=0,"",SUMPRODUCT(($A$7:$A$26=1)*($C$7:$C$26="Good")*(G7:G26))/SUMPRODUCT(($A$7:$A$26=1)*($C$7:$C$26="Good"))) | H33: =IF(SUMPRODUCT(($A$7:$A$26=1)*($C$7:$C$26="Good"))=0,"",SUMPRODUCT(($A$7:$A$26=1)*($C$7:$C$26="Good")*(H7:H26))/SUMPRODUCT(($A$7:$A$26=1)*($C$7:$C$26="Good"))) | I33: =IF(SUMPRODUCT(($A$7:$A$26=1)*($C$7:$C$26="Good"))=0,"",SUMPRODUCT(($A$7:$A$26=1)*($C$7:$C$26="Good")*(I7:I26))/SUMPRODUCT(($A$7:$A$26=1)*($C$7:$C$26="Good"))) | J33: =IF(SUMPRODUCT(($A$7:$A$26=1)*($C$7:$C$26="Good"))=0,"",SUMPRODUCT(($A$7:$A$26=1)*($C$7:$C$26="Good")*(J7:J26))/SUMPRODUCT(($A$7:$A$26=1)*($C$7:$C$26="Good"))) | K33: =IF(SUMPRODUCT(($A$7:$A$26=1)*($C$7:$C$26="Good"))=0,"",SUMPRODUCT(($A$7:$A$26=1)*($C$7:$C$26="Good")*(K7:K26))/SUMPRODUCT(($A$7:$A$26=1)*($C$7:$C$26="Good"))) | L33: =IF(SUMPRODUCT(($A$7:$A$26=1)*($C$7:$C$26="Good"))=0,"",SUMPRODUCT(($A$7:$A$26=1)*($C$7:$C$26="Good")*(L7:L26))/SUMPRODUCT(($A$7:$A$26=1)*($C$7:$C$26="Good"))) | ... AI33: =IF(SUMPRODUCT(($A$7:$A$26=1)*($C$7:$C$26="Good"))=0,"",SUMPRODUCT(($A$7:$A$26=1)*($C$7:$C$26="Good")*(AI7:AI26))/SUMPRODUCT(($A$7:$A$26=1)*($C$7:$C$26="Good"))) | AL33: Net score | AM33: =SUMPRODUCT(($E$6:$AI$6<=$B$3)*(E32:AI32))
AL34: Avg completion (Good) | AM34: =AVERAGEIF($E$6:$AI$6,"<="&$B$3,E33:AI33)

Sheet Feb
A1: Feb Habit Tracker
A2: Year: | B2: =Setup!$B$3 | C2: Month: | D2: Feb
A3: Days in month: | B3: =DAY(EOMONTH(DATE(Setup!$B$3,2,1),0))
E5: =TEXT(DATE(Setup!$B$3,2,1),"ddd") | F5: =TEXT(DATE(Setup!$B$3,2,2),"ddd") | G5: =TEXT(DATE(Setup!$B$3,2,3),"ddd") | H5: =TEXT(DATE(Setup!$B$3,2,4),"ddd") | I5: =TEXT(DATE(Setup!$B$3,2,5),"ddd") | J5: =TEXT(DATE(Setup!$B$3,2,6),"ddd") | K5: =TEXT(DATE(Setup!$B$3,2,7),"ddd") | L5: =TEXT(DATE(Setup!$B$3,2,8),"ddd") | M5: =TEXT(DATE(Setup!$B$3,2,9),"ddd") | N5: =TEXT(DATE(Setup!$B$3,2,10),"ddd") | O5: =TEXT(DATE(Setup!$B$3,2,11),"ddd") | P5: =TEXT(DATE(Setup!$B$3,2,12),"ddd") | Q5: =TEXT(DATE(Setup!$B$3,2,13),"ddd") | R5: =TEXT(DATE(Setup!$B$3,2,14),"ddd") | S5: =TEXT(DATE(Setup!$B$3,2,15),"ddd") | T5: =TEXT(DATE(Setup!$B$3,2,16),"ddd") | U5: =TEXT(DATE(Setup!$B$3,2,17),"ddd") | V5: =TEXT(DATE(Setup!$B$3,2,18),"ddd") | W5: =TEXT(DATE(Setup!$B$3,2,19),"ddd") | X5: =TEXT(DATE(Setup!$B$3,2,20),"ddd") | Y5: =TEXT(DATE(Setup!$B$3,2,21),"ddd") | Z5: =TEXT(DATE(Setup!$B$3,2,22),"ddd") | AA5: =TEXT(DATE(Setup!$B$3,2,23),"ddd") | AB5: =TEXT(DATE(Setup!$B$3,2,24),"ddd") | AC5: =TEXT(DATE(Setup!$B$3,2,25),"ddd") | AD5: =TEXT(DATE(Setup!$B$3,2,26),"ddd") | AE5: =TEXT(DATE(Setup!$B$3,2,27),"ddd") | AF5: =TEXT(DATE(Setup!$B$3,2,28),"ddd") | AG5: =TEXT(DATE(Setup!$B$3,2,29),"ddd") | AH5: =TEXT(DATE(Setup!$B$3,2,30),"ddd") | AI5: =TEXT(DATE(Setup!$B$3,2,31),"ddd")
A6: Active | B6: Habit | C6: Type | D6: Points | E6: 1 | F6: 2 | G6: 3 | H6: 4 | I6: 5 | J6: 6 | K6: 7 | L6: 8 | M6: 9 | N6: 10 | O6: 11 | P6: 12 | Q6: 13 | R6: 14 | S6: 15 | T6: 16 | U6: 17 | V6: 18 | W6: 19 | X6: 20 | Y6: 21 | Z6: 22 | AA6: 23 | AB6: 24 | AC6: 25 | AD6: 26 | AE6: 27 | AF6: 28 | AG6: 29 | AH6: 30 | AI6: 31 | AJ6: Total
A7: =Setup!D9 | B7: =Setup!A9 | C7: =Setup!B9 | D7: =Setup!E9 | AJ7: =IF($A7=1,SUMPRODUCT(($E$6:$AI$6<=$B$3)*(E7:AI7)),"")
A8: =Setup!D10 | B8: =Setup!A10 | C8: =Setup!B10 | D8: =Setup!E10 | AJ8: =IF($A8=1,SUMPRODUCT(($E$6:$AI$6<=$B$3)*(E8:AI8)),"")
A9: =Setup!D11 | B9: =Setup!A11 | C9: =Setup!B11 | D9: =Setup!E11 | AJ9: =IF($A9=1,SUMPRODUCT(($E$6:$AI$6<=$B$3)*(E9:AI9)),"")
A10: =Setup!D12 | B10: =Setup!A12 | C10: =Setup!B12 | D10: =Setup!E12 | AJ10: =IF($A10=1,SUMPRODUCT(($E$6:$AI$6<=$B$3)*(E10:AI10)),"")
A11: =Setup!D13 | B11: =Setup!A13 | C11: =Setup!B13 | D11: =Setup!E13 | AJ11: =IF($A11=1,SUMPRODUCT(($E$6:$AI$6<=$B$3)*(E11:AI11)),"")
A12: =Setup!D14 | B12: =Setup!A14 | C12: =Setup!B14 | D12: =Setup!E14 | AJ12: =IF($A12=1,SUMPRODUCT(($E$6:$AI$6<=$B$3)*(E12:AI12)),"")
A13: =Setup!D15 | B13: =Setup!A15 | C13: =Setup!B15 | D13: =Setup!E15 | AJ13: =IF($A13=1,SUMPRODUCT(($E$6:$AI$6<=$B$3)*(E13:AI13)),"")
A14: =Setup!D16 | B14: =Setup!A16 | C14: =Setup!B16 | D14: =Setup!E16 | AJ14: =IF($A14=1,SUMPRODUCT(($E$6:$AI$6<=$B$3)*(E14:AI14)),"")
A15: =Setup!D17 | B15: =Setup!A17 | C15: =Setup!B17 | D15: =Setup!E17 | AJ15: =IF($A15=1,SUMPRODUCT(($E$6:$AI$6<=$B$3)*(E15:AI15)),"")
A16: =Setup!D18 | B16: =Setup!A18 | C16: =Setup!B18 | D16: =Setup!E18 | AJ16: =IF($A16=1,SUMPRODUCT(($E$6:$AI$6<=$B$3)*(E16:AI16)),"")
A17: =Setup!D19 | B17: =Setup!A19 | C17: =Setup!B19 | D17: =Setup!E19 | AJ17: =IF($A17=1,SUMPRODUCT(($E$6:$AI$6<=$B$3)*(E17:AI17)),"")
A18: =Setup!D20 | B18: =Setup!A20 | C18: =Setup!B20 | D18: =Setup!E20 | AJ18: =IF($A18=1,SUMPRODUCT(($E$6:$AI$6<=$B$3)*(E18:AI18)),"")
... A26: =Setup!D28 | B26: =Setup!A28 | C26: =Setup!B28 | D26: =Setup!E28 | AJ26: =IF($A26=1,SUMPRODUCT(($E$6:$AI$6<=$B$3)*(E26:AI26)),"")
A29: Daily summary
A30: Good habits done | E30: =SUMPRODUCT(($A$7:$A$26=1)*($C$7:$C$26="Good")*(E7:E26)) | F30: =SUMPRODUCT(($A$7:$A$26=1)*($C$7:$C$26="Good")*(F7:F26)) | G30: =SUMPRODUCT(($A$7:$A$26=1)*($C$7:$C$26="Good")*(G7:G26)) | H30: =SUMPRODUCT(($A$7:$A$26=1)*($C$7:$C$26="Good")*(H7:H26)) | I30: =SUMPRODUCT(($A$7:$A$26=1)*($C$7:$C$26="Good")*(I7:I26)) | J30: =SUMPRODUCT(($A$7:$A$26=1)*($C$7:$C$26="Good")*(J7:J26)) | K30: =SUMPRODUCT(($A$7:$A$26=1)*($C$7:$C$26="Good")*(K7:K26)) | L30: =SUMPRODUCT(($A$7:$A$26=1)*($C$7:$C$26="Good")*(L7:L26)) | ... AI30: =SUMPRODUCT(($A$7:$A$26=1)*($C$7:$C$26="Good")*(AI7:AI26)) | AL30: Monthly totals
A31: Bad habits happened | E31: =SUMPRODUCT(($A$7:$A$26=1)*($C$7:$C$26="Bad")*(E7:E26)) | F31: =SUMPRODUCT(($A$7:$A$26=1)*($C$7:$C$26="Bad")*(F7:F26)) | G31: =SUMPRODUCT(($A$7:$A$26=1)*($C$7:$C$26="Bad")*(G7:G26)) | H31: =SUMPRODUCT(($A$7:$A$26=1)*($C$7:$C$26="Bad")*(H7:H26)) | I31: =SUMPRODUCT(($A$7:$A$26=1)*($C$7:$C$26="Bad")*(I7:I26)) | J31: =SUMPRODUCT(($A$7:$A$26=1)*($C$7:$C$26="Bad")*(J7:J26)) | K31: =SUMPRODUCT(($A$7:$A$26=1)*($C$7:$C$26="Bad")*(K7:K26)) | L31: =SUMPRODUCT(($A$7:$A$26=1)*($C$7:$C$26="Bad")*(L7:L26)) | ... AI31: =SUMPRODUCT(($A$7:$A$26=1)*($C$7:$C$26="Bad")*(AI7:AI26)) | AL31: Good done | AM31: =SUMPRODUCT(($E$6:$AI$6<=$B$3)*(E30:AI30))
A32: Net score | E32: =SUMPRODUCT(($A$7:$A$26=1)*($D$7:$D$26)*(E7:E26)) | F32: =SUMPRODUCT(($A$7:$A$26=1)*($D$7:$D$26)*(F7:F26)) | G32: =SUMPRODUCT(($A$7:$A$26=1)*($D$7:$D$26)*(G7:G26)) | H32: =SUMPRODUCT(($A$7:$A$26=1)*($D$7:$D$26)*(H7:H26)) | I32: =SUMPRODUCT(($A$7:$A$26=1)*($D$7:$D$26)*(I7:I26)) | J32: =SUMPRODUCT(($A$7:$A$26=1)*($D$7:$D$26)*(J7:J26)) | K32: =SUMPRODUCT(($A$7:$A$26=1)*($D$7:$D$26)*(K7:K26)) | L32: =SUMPRODUCT(($A$7:$A$26=1)*($D$7:$D$26)*(L7:L26)) | ... AI32: =SUMPRODUCT(($A$7:$A$26=1)*($D$7:$D$26)*(AI7:AI26)) | AL32: Bad happened | AM32: =SUMPRODUCT(($E$6:$AI$6<=$B$3)*(E31:AI31))
A33: Completion % (Good only) | E33: =IF(SUMPRODUCT(($A$7:$A$26=1)*($C$7:$C$26="Good"))=0,"",SUMPRODUCT(($A$7:$A$26=1)*($C$7:$C$26="Good")*(E7:E26))/SUMPRODUCT(($A$7:$A$26=1)*($C$7:$C$26="Good"))) | F33: =IF(SUMPRODUCT(($A$7:$A$26=1)*($C$7:$C$26="Good"))=0,"",SUMPRODUCT(($A$7:$A$26=1)*($C$7:$C$26="Good")*(F7:F26))/SUMPRODUCT(($A$7:$A$26=1)*($C$7:$C$26="Good"))) | G33: =IF(SUMPRODUCT(($A$7:$A$26=1)*($C$7:$C$26="Good"))=0,"",SUMPRODUCT(($A$7:$A$26=1)*($C$7:$C$26="Good")*(G7:G26))/SUMPRODUCT(($A$7:$A$26=1)*($C$7:$C$26="Good"))) | H33: =IF(SUMPRODUCT(($A$7:$A$26=1)*($C$7:$C$26="Good"))=0,"",SUMPRODUCT(($A$7:$A$26=1)*($C$7:$C$26="Good")*(H7:H26))/SUMPRODUCT(($A$7:$A$26=1)*($C$7:$C$26="Good"))) | I33: =IF(SUMPRODUCT(($A$7:$A$26=1)*($C$7:$C$26="Good"))=0,"",SUMPRODUCT(($A$7:$A$26=1)*($C$7:$C$26="Good")*(I7:I26))/SUMPRODUCT(($A$7:$A$26=1)*($C$7:$C$26="Good"))) | J33: =IF(SUMPRODUCT(($A$7:$A$26=1)*($C$7:$C$26="Good"))=0,"",SUMPRODUCT(($A$7:$A$26=1)*($C$7:$C$26="Good")*(J7:J26))/SUMPRODUCT(($A$7:$A$26=1)*($C$7:$C$26="Good"))) | K33: =IF(SUMPRODUCT(($A$7:$A$26=1)*($C$7:$C$26="Good"))=0,"",SUMPRODUCT(($A$7:$A$26=1)*($C$7:$C$26="Good")*(K7:K26))/SUMPRODUCT(($A$7:$A$26=1)*($C$7:$C$26="Good"))) | L33: =IF(SUMPRODUCT(($A$7:$A$26=1)*($C$7:$C$26="Good"))=0,"",SUMPRODUCT(($A$7:$A$26=1)*($C$7:$C$26="Good")*(L7:L26))/SUMPRODUCT(($A$7:$A$26=1)*($C$7:$C$26="Good"))) | ... AI33: =IF(SUMPRODUCT(($A$7:$A$26=1)*($C$7:$C$26="Good"))=0,"",SUMPRODUCT(($A$7:$A$26=1)*($C$7:$C$26="Good")*(AI7:AI26))/SUMPRODUCT(($A$7:$A$26=1)*($C$7:$C$26="Good"))) | AL33: Net score | AM33: =SUMPRODUCT(($E$6:$AI$6<=$B$3)*(E32:AI32))
AL34: Avg completion (Good) | AM34: =AVERAGEIF($E$6:$AI$6,"<="&$B$3,E33:AI33)

Sheet Mar
A1: Mar Habit Tracker
A2: Year: | B2: =Setup!$B$3 | C2: Month: | D2: Mar
A3: Days in month: | B3: =DAY(EOMONTH(DATE(Setup!$B$3,3,1),0))
E5: =TEXT(DATE(Setup!$B$3,3,1),"ddd") | F5: =TEXT(DATE(Setup!$B$3,3,2),"ddd") | G5: =TEXT(DATE(Setup!$B$3,3,3),"ddd") | H5: =TEXT(DATE(Setup!$B$3,3,4),"ddd") | I5: =TEXT(DATE(Setup!$B$3,3,5),"ddd") | J5: =TEXT(DATE(Setup!$B$3,3,6),"ddd") | K5: =TEXT(DATE(Setup!$B$3,3,7),"ddd") | L5: =TEXT(DATE(Setup!$B$3,3,8),"ddd") | M5: =TEXT(DATE(Setup!$B$3,3,9),"ddd") | N5: =TEXT(DATE(Setup!$B$3,3,10),"ddd") | O5: =TEXT(DATE(Setup!$B$3,3,11),"ddd") | P5: =TEXT(DATE(Setup!$B$3,3,12),"ddd") | Q5: =TEXT(DATE(Setup!$B$3,3,13),"ddd") | R5: =TEXT(DATE(Setup!$B$3,3,14),"ddd") | S5: =TEXT(DATE(Setup!$B$3,3,15),"ddd") | T5: =TEXT(DATE(Setup!$B$3,3,16),"ddd") | U5: =TEXT(DATE(Setup!$B$3,3,17),"ddd") | V5: =TEXT(DATE(Setup!$B$3,3,18),"ddd") | W5: =TEXT(DATE(Setup!$B$3,3,19),"ddd") | X5: =TEXT(DATE(Setup!$B$3,3,20),"ddd") | Y5: =TEXT(DATE(Setup!$B$3,3,21),"ddd") | Z5: =TEXT(DATE(Setup!$B$3,3,22),"ddd") | AA5: =TEXT(DATE(Setup!$B$3,3,23),"ddd") | AB5: =TEXT(DATE(Setup!$B$3,3,24),"ddd") | AC5: =TEXT(DATE(Setup!$B$3,3,25),"ddd") | AD5: =TEXT(DATE(Setup!$B$3,3,26),"ddd") | AE5: =TEXT(DATE(Setup!$B$3,3,27),"ddd") | AF5: =TEXT(DATE(Setup!$B$3,3,28),"ddd") | AG5: =TEXT(DATE(Setup!$B$3,3,29),"ddd") | AH5: =TEXT(DATE(Setup!$B$3,3,30),"ddd") | AI5: =TEXT(DATE(Setup!$B$3,3,31),"ddd")
A6: Active | B6: Habit | C6: Type | D6: Points | E6: 1 | F6: 2 | G6: 3 | H6: 4 | I6: 5 | J6: 6 | K6: 7 | L6: 8 | M6: 9 | N6: 10 | O6: 11 | P6: 12 | Q6: 13 | R6: 14 | S6: 15 | T6: 16 | U6: 17 | V6: 18 | W6: 19 | X6: 20 | Y6: 21 | Z6: 22 | AA6: 23 | AB6: 24 | AC6: 25 | AD6: 26 | AE6: 27 | AF6: 28 | AG6: 29 | AH6: 30 | AI6: 31 | AJ6: Total
A7: =Setup!D9 | B7: =Setup!A9 | C7: =Setup!B9 | D7: =Setup!E9 | AJ7: =IF($A7=1,SUMPRODUCT(($E$6:$AI$6<=$B$3)*(E7:AI7)),"")
A8: =Setup!D10 | B8: =Setup!A10 | C8: =Setup!B10 | D8: =Setup!E10 | AJ8: =IF($A8=1,SUMPRODUCT(($E$6:$AI$6<=$B$3)*(E8:AI8)),"")
A9: =Setup!D11 | B9: =Setup!A11 | C9: =Setup!B11 | D9: =Setup!E11 | AJ9: =IF($A9=1,SUMPRODUCT(($E$6:$AI$6<=$B$3)*(E9:AI9)),"")
A10: =Setup!D12 | B10: =Setup!A12 | C10: =Setup!B12 | D10: =Setup!E12 | AJ10: =IF($A10=1,SUMPRODUCT(($E$6:$AI$6<=$B$3)*(E10:AI10)),"")
A11: =Setup!D13 | B11: =Setup!A13 | C11: =Setup!B13 | D11: =Setup!E13 | AJ11: =IF($A11=1,SUMPRODUCT(($E$6:$AI$6<=$B$3)*(E11:AI11)),"")
A12: =Setup!D14 | B12: =Setup!A14 | C12: =Setup!B14 | D12: =Setup!E14 | AJ12: =IF($A12=1,SUMPRODUCT(($E$6:$AI$6<=$B$3)*(E12:AI12)),"")
A13: =Setup!D15 | B13: =Setup!A15 | C13: =Setup!B15 | D13: =Setup!E15 | AJ13: =IF($A13=1,SUMPRODUCT(($E$6:$AI$6<=$B$3)*(E13:AI13)),"")
A14: =Setup!D16 | B14: =Setup!A16 | C14: =Setup!B16 | D14: =Setup!E16 | AJ14: =IF($A14=1,SUMPRODUCT(($E$6:$AI$6<=$B$3)*(E14:AI14)),"")
A15: =Setup!D17 | B15: =Setup!A17 | C15: =Setup!B17 | D15: =Setup!E17 | AJ15: =IF($A15=1,SUMPRODUCT(($E$6:$AI$6<=$B$3)*(E15:AI15)),"")
A16: =Setup!D18 | B16: =Setup!A18 | C16: =Setup!B18 | D16: =Setup!E18 | AJ16: =IF($A16=1,SUMPRODUCT(($E$6:$AI$6<=$B$3)*(E16:AI16)),"")
A17: =Setup!D19 | B17: =Setup!A19 | C17: =Setup!B19 | D17: =Setup!E19 | AJ17: =IF($A17=1,SUMPRODUCT(($E$6:$AI$6<=$B$3)*(E17:AI17)),"")
A18: =Setup!D20 | B18: =Setup!A20 | C18: =Setup!B20 | D18: =Setup!E20 | AJ18: =IF($A18=1,SUMPRODUCT(($E$6:$AI$6<=$B$3)*(E18:AI18)),"")
... A26: =Setup!D28 | B26: =Setup!A28 | C26: =Setup!B28 | D26: =Setup!E28 | AJ26: =IF($A26=1,SUMPRODUCT(($E$6:$AI$6<=$B$3)*(E26:AI26)),"")
A29: Daily summary
A30: Good habits done | E30: =SUMPRODUCT(($A$7:$A$26=1)*($C$7:$C$26="Good")*(E7:E26)) | F30: =SUMPRODUCT(($A$7:$A$26=1)*($C$7:$C$26="Good")*(F7:F26)) | G30: =SUMPRODUCT(($A$7:$A$26=1)*($C$7:$C$26="Good")*(G7:G26)) | H30: =SUMPRODUCT(($A$7:$A$26=1)*($C$7:$C$26="Good")*(H7:H26)) | I30: =SUMPRODUCT(($A$7:$A$26=1)*($C$7:$C$26="Good")*(I7:I26)) | J30: =SUMPRODUCT(($A$7:$A$26=1)*($C$7:$C$26="Good")*(J7:J26)) | K30: =SUMPRODUCT(($A$7:$A$26=1)*($C$7:$C$26="Good")*(K7:K26)) | L30: =SUMPRODUCT(($A$7:$A$26=1)*($C$7:$C$26="Good")*(L7:L26)) | ... AI30: =SUMPRODUCT(($A$7:$A$26=1)*($C$7:$C$26="Good")*(AI7:AI26)) | AL30: Monthly totals
A31: Bad habits happened | E31: =SUMPRODUCT(($A$7:$A$26=1)*($C$7:$C$26="Bad")*(E7:E26)) | F31: =SUMPRODUCT(($A$7:$A$26=1)*($C$7:$C$26="Bad")*(F7:F26)) | G31: =SUMPRODUCT(($A$7:$A$26=1)*($C$7:$C$26="Bad")*(G7:G26)) | H31: =SUMPRODUCT(($A$7:$A$26=1)*($C$7:$C$26="Bad")*(H7:H26)) | I31: =SUMPRODUCT(($A$7:$A$26=1)*($C$7:$C$26="Bad")*(I7:I26)) | J31: =SUMPRODUCT(($A$7:$A$26=1)*($C$7:$C$26="Bad")*(J7:J26)) | K31: =SUMPRODUCT(($A$7:$A$26=1)*($C$7:$C$26="Bad")*(K7:K26)) | L31: =SUMPRODUCT(($A$7:$A$26=1)*($C$7:$C$26="Bad")*(L7:L26)) | ... AI31: =SUMPRODUCT(($A$7:$A$26=1)*($C$7:$C$26="Bad")*(AI7:AI26)) | AL31: Good done | AM31: =SUMPRODUCT(($E$6:$AI$6<=$B$3)*(E30:AI30))
A32: Net score | E32: =SUMPRODUCT(($A$7:$A$26=1)*($D$7:$D$26)*(E7:E26)) | F32: =SUMPRODUCT(($A$7:$A$26=1)*($D$7:$D$26)*(F7:F26)) | G32: =SUMPRODUCT(($A$7:$A$26=1)*($D$7:$D$26)*(G7:G26)) | H32: =SUMPRODUCT(($A$7:$A$26=1)*($D$7:$D$26)*(H7:H26)) | I32: =SUMPRODUCT(($A$7:$A$26=1)*($D$7:$D$26)*(I7:I26)) | J32: =SUMPRODUCT(($A$7:$A$26=1)*($D$7:$D$26)*(J7:J26)) | K32: =SUMPRODUCT(($A$7:$A$26=1)*($D$7:$D$26)*(K7:K26)) | L32: =SUMPRODUCT(($A$7:$A$26=1)*($D$7:$D$26)*(L7:L26)) | ... AI32: =SUMPRODUCT(($A$7:$A$26=1)*($D$7:$D$26)*(AI7:AI26)) | AL32: Bad happened | AM32: =SUMPRODUCT(($E$6:$AI$6<=$B$3)*(E31:AI31))
A33: Completion % (Good only) | E33: =IF(SUMPRODUCT(($A$7:$A$26=1)*($C$7:$C$26="Good"))=0,"",SUMPRODUCT(($A$7:$A$26=1)*($C$7:$C$26="Good")*(E7:E26))/SUMPRODUCT(($A$7:$A$26=1)*($C$7:$C$26="Good"))) | F33: =IF(SUMPRODUCT(($A$7:$A$26=1)*($C$7:$C$26="Good"))=0,"",SUMPRODUCT(($A$7:$A$26=1)*($C$7:$C$26="Good")*(F7:F26))/SUMPRODUCT(($A$7:$A$26=1)*($C$7:$C$26="Good"))) | G33: =IF(SUMPRODUCT(($A$7:$A$26=1)*($C$7:$C$26="Good"))=0,"",SUMPRODUCT(($A$7:$A$26=1)*($C$7:$C$26="Good")*(G7:G26))/SUMPRODUCT(($A$7:$A$26=1)*($C$7:$C$26="Good"))) | H33: =IF(SUMPRODUCT(($A$7:$A$26=1)*($C$7:$C$26="Good"))=0,"",SUMPRODUCT(($A$7:$A$26=1)*($C$7:$C$26="Good")*(H7:H26))/SUMPRODUCT(($A$7:$A$26=1)*($C$7:$C$26="Good"))) | I33: =IF(SUMPRODUCT(($A$7:$A$26=1)*($C$7:$C$26="Good"))=0,"",SUMPRODUCT(($A$7:$A$26=1)*($C$7:$C$26="Good")*(I7:I26))/SUMPRODUCT(($A$7:$A$26=1)*($C$7:$C$26="Good"))) | J33: =IF(SUMPRODUCT(($A$7:$A$26=1)*($C$7:$C$26="Good"))=0,"",SUMPRODUCT(($A$7:$A$26=1)*($C$7:$C$26="Good")*(J7:J26))/SUMPRODUCT(($A$7:$A$26=1)*($C$7:$C$26="Good"))) | K33: =IF(SUMPRODUCT(($A$7:$A$26=1)*($C$7:$C$26="Good"))=0,"",SUMPRODUCT(($A$7:$A$26=1)*($C$7:$C$26="Good")*(K7:K26))/SUMPRODUCT(($A$7:$A$26=1)*($C$7:$C$26="Good"))) | L33: =IF(SUMPRODUCT(($A$7:$A$26=1)*($C$7:$C$26="Good"))=0,"",SUMPRODUCT(($A$7:$A$26=1)*($C$7:$C$26="Good")*(L7:L26))/SUMPRODUCT(($A$7:$A$26=1)*($C$7:$C$26="Good"))) | ... AI33: =IF(SUMPRODUCT(($A$7:$A$26=1)*($C$7:$C$26="Good"))=0,"",SUMPRODUCT(($A$7:$A$26=1)*($C$7:$C$26="Good")*(AI7:AI26))/SUMPRODUCT(($A$7:$A$26=1)*($C$7:$C$26="Good"))) | AL33: Net score | AM33: =SUMPRODUCT(($E$6:$AI$6<=$B$3)*(E32:AI32))
AL34: Avg completion (Good) | AM34: =AVERAGEIF($E$6:$AI$6,"<="&$B$3,E33:AI33)

Sheet Apr
A1: Apr Habit Tracker
A2: Year: | B2: =Setup!$B$3 | C2: Month: | D2: Apr
A3: Days in month: | B3: =DAY(EOMONTH(DATE(Setup!$B$3,4,1),0))
E5: =TEXT(DATE(Setup!$B$3,4,1),"ddd") | F5: =TEXT(DATE(Setup!$B$3,4,2),"ddd") | G5: =TEXT(DATE(Setup!$B$3,4,3),"ddd") | H5: =TEXT(DATE(Setup!$B$3,4,4),"ddd") | I5: =TEXT(DATE(Setup!$B$3,4,5),"ddd") | J5: =TEXT(DATE(Setup!$B$3,4,6),"ddd") | K5: =TEXT(DATE(Setup!$B$3,4,7),"ddd") | L5: =TEXT(DATE(Setup!$B$3,4,8),"ddd") | M5: =TEXT(DATE(Setup!$B$3,4,9),"ddd") | N5: =TEXT(DATE(Setup!$B$3,4,10),"ddd") | O5: =TEXT(DATE(Setup!$B$3,4,11),"ddd") | P5: =TEXT(DATE(Setup!$B$3,4,12),"ddd") | Q5: =TEXT(DATE(Setup!$B$3,4,13),"ddd") | R5: =TEXT(DATE(Setup!$B$3,4,14),"ddd") | S5: =TEXT(DATE(Setup!$B$3,4,15),"ddd") | T5: =TEXT(DATE(Setup!$B$3,4,16),"ddd") | U5: =TEXT(DATE(Setup!$B$3,4,17),"ddd") | V5: =TEXT(DATE(Setup!$B$3,4,18),"ddd") | W5: =TEXT(DATE(Setup!$B$3,4,19),"ddd") | X5: =TEXT(DATE(Setup!$B$3,4,20),"ddd") | Y5: =TEXT(DATE(Setup!$B$3,4,21),"ddd") | Z5: =TEXT(DATE(Setup!$B$3,4,22),"ddd") | AA5: =TEXT(DATE(Setup!$B$3,4,23),"ddd") | AB5: =TEXT(DATE(Setup!$B$3,4,24),"ddd") | AC5: =TEXT(DATE(Setup!$B$3,4,25),"ddd") | AD5: =TEXT(DATE(Setup!$B$3,4,26),"ddd") | AE5: =TEXT(DATE(Setup!$B$3,4,27),"ddd") | AF5: =TEXT(DATE(Setup!$B$3,4,28),"ddd") | AG5: =TEXT(DATE(Setup!$B$3,4,29),"ddd") | AH5: =TEXT(DATE(Setup!$B$3,4,30),"ddd") | AI5: =TEXT(DATE(Setup!$B$3,4,31),"ddd")
A6: Active | B6: Habit | C6: Type | D6: Points | E6: 1 | F6: 2 | G6: 3 | H6: 4 | I6: 5 | J6: 6 | K6: 7 | L6: 8 | M6: 9 | N6: 10 | O6: 11 | P6: 12 | Q6: 13 | R6: 14 | S6: 15 | T6: 16 | U6: 17 | V6: 18 | W6: 19 | X6: 20 | Y6: 21 | Z6: 22 | AA6: 23 | AB6: 24 | AC6: 25 | AD6: 26 | AE6: 27 | AF6: 28 | AG6: 29 | AH6: 30 | AI6: 31 | AJ6: Total
A7: =Setup!D9 | B7: =Setup!A9 | C7: =Setup!B9 | D7: =Setup!E9 | AJ7: =IF($A7=1,SUMPRODUCT(($E$6:$AI$6<=$B$3)*(E7:AI7)),"")
A8: =Setup!D10 | B8: =Setup!A10 | C8: =Setup!B10 | D8: =Setup!E10 | AJ8: =IF($A8=1,SUMPRODUCT(($E$6:$AI$6<=$B$3)*(E8:AI8)),"")
A9: =Setup!D11 | B9: =Setup!A11 | C9: =Setup!B11 | D9: =Setup!E11 | AJ9: =IF($A9=1,SUMPRODUCT(($E$6:$AI$6<=$B$3)*(E9:AI9)),"")
A10: =Setup!D12 | B10: =Setup!A12 | C10: =Setup!B12 | D10: =Setup!E12 | AJ10: =IF($A10=1,SUMPRODUCT(($E$6:$AI$6<=$B$3)*(E10:AI10)),"")
A11: =Setup!D13 | B11: =Setup!A13 | C11: =Setup!B13 | D11: =Setup!E13 | AJ11: =IF($A11=1,SUMPRODUCT(($E$6:$AI$6<=$B$3)*(E11:AI11)),"")
A12: =Setup!D14 | B12: =Setup!A14 | C12: =Setup!B14 | D12: =Setup!E14 | AJ12: =IF($A12=1,SUMPRODUCT(($E$6:$AI$6<=$B$3)*(E12:AI12)),"")
A13: =Setup!D15 | B13: =Setup!A15 | C13: =Setup!B15 | D13: =Setup!E15 | AJ13: =IF($A13=1,SUMPRODUCT(($E$6:$AI$6<=$B$3)*(E13:AI13)),"")
A14: =Setup!D16 | B14: =Setup!A16 | C14: =Setup!B16 | D14: =Setup!E16 | AJ14: =IF($A14=1,SUMPRODUCT(($E$6:$AI$6<=$B$3)*(E14:AI14)),"")
A15: =Setup!D17 | B15: =Setup!A17 | C15: =Setup!B17 | D15: =Setup!E17 | AJ15: =IF($A15=1,SUMPRODUCT(($E$6:$AI$6<=$B$3)*(E15:AI15)),"")
A16: =Setup!D18 | B16: =Setup!A18 | C16: =Setup!B18 | D16: =Setup!E18 | AJ16: =IF($A16=1,SUMPRODUCT(($E$6:$AI$6<=$B$3)*(E16:AI16)),"")
A17: =Setup!D19 | B17: =Setup!A19 | C17: =Setup!B19 | D17: =Setup!E19 | AJ17: =IF($A17=1,SUMPRODUCT(($E$6:$AI$6<=$B$3)*(E17:AI17)),"")
A18: =Setup!D20 | B18: =Setup!A20 | C18: =Setup!B20 | D18: =Setup!E20 | AJ18: =IF($A18=1,SUMPRODUCT(($E$6:$AI$6<=$B$3)*(E18:AI18)),"")
... A26: =Setup!D28 | B26: =Setup!A28 | C26: =Setup!B28 | D26: =Setup!E28 | AJ26: =IF($A26=1,SUMPRODUCT(($E$6:$AI$6<=$B$3)*(E26:AI26)),"")
A29: Daily summary
A30: Good habits done | E30: =SUMPRODUCT(($A$7:$A$26=1)*($C$7:$C$26="Good")*(E7:E26)) | F30: =SUMPRODUCT(($A$7:$A$26=1)*($C$7:$C$26="Good")*(F7:F26)) | G30: =SUMPRODUCT(($A$7:$A$26=1)*($C$7:$C$26="Good")*(G7:G26)) | H30: =SUMPRODUCT(($A$7:$A$26=1)*($C$7:$C$26="Good")*(H7:H26)) | I30: =SUMPRODUCT(($A$7:$A$26=1)*($C$7:$C$26="Good")*(I7:I26)) | J30: =SUMPRODUCT(($A$7:$A$26=1)*($C$7:$C$26="Good")*(J7:J26)) | K30: =SUMPRODUCT(($A$7:$A$26=1)*($C$7:$C$26="Good")*(K7:K26)) | L30: =SUMPRODUCT(($A$7:$A$26=1)*($C$7:$C$26="Good")*(L7:L26)) | ... AI30: =SUMPRODUCT(($A$7:$A$26=1)*($C$7:$C$26="Good")*(AI7:AI26)) | AL30: Monthly totals
A31: Bad habits happened | E31: =SUMPRODUCT(($A$7:$A$26=1)*($C$7:$C$26="Bad")*(E7:E26)) | F31: =SUMPRODUCT(($A$7:$A$26=1)*($C$7:$C$26="Bad")*(F7:F26)) | G31: =SUMPRODUCT(($A$7:$A$26=1)*($C$7:$C$26="Bad")*(G7:G26)) | H31: =SUMPRODUCT(($A$7:$A$26=1)*($C$7:$C$26="Bad")*(H7:H26)) | I31: =SUMPRODUCT(($A$7:$A$26=1)*($C$7:$C$26="Bad")*(I7:I26)) | J31: =SUMPRODUCT(($A$7:$A$26=1)*($C$7:$C$26="Bad")*(J7:J26)) | K31: =SUMPRODUCT(($A$7:$A$26=1)*($C$7:$C$26="Bad")*(K7:K26)) | L31: =SUMPRODUCT(($A$7:$A$26=1)*($C$7:$C$26="Bad")*(L7:L26)) | ... AI31: =SUMPRODUCT(($A$7:$A$26=1)*($C$7:$C$26="Bad")*(AI7:AI26)) | AL31: Good done | AM31: =SUMPRODUCT(($E$6:$AI$6<=$B$3)*(E30:AI30))
A32: Net score | E32: =SUMPRODUCT(($A$7:$A$26=1)*($D$7:$D$26)*(E7:E26)) | F32: =SUMPRODUCT(($A$7:$A$26=1)*($D$7:$D$26)*(F7:F26)) | G32: =SUMPRODUCT(($A$7:$A$26=1)*($D$7:$D$26)*(G7:G26)) | H32: =SUMPRODUCT(($A$7:$A$26=1)*($D$7:$D$26)*(H7:H26)) | I32: =SUMPRODUCT(($A$7:$A$26=1)*($D$7:$D$26)*(I7:I26)) | J32: =SUMPRODUCT(($A$7:$A$26=1)*($D$7:$D$26)*(J7:J26)) | K32: =SUMPRODUCT(($A$7:$A$26=1)*($D$7:$D$26)*(K7:K26)) | L32: =SUMPRODUCT(($A$7:$A$26=1)*($D$7:$D$26)*(L7:L26)) | ... AI32: =SUMPRODUCT(($A$7:$A$26=1)*($D$7:$D$26)*(AI7:AI26)) | AL32: Bad happened | AM32: =SUMPRODUCT(($E$6:$AI$6<=$B$3)*(E31:AI31))
A33: Completion % (Good only) | E33: =IF(SUMPRODUCT(($A$7:$A$26=1)*($C$7:$C$26="Good"))=0,"",SUMPRODUCT(($A$7:$A$26=1)*($C$7:$C$26="Good")*(E7:E26))/SUMPRODUCT(($A$7:$A$26=1)*($C$7:$C$26="Good"))) | F33: =IF(SUMPRODUCT(($A$7:$A$26=1)*($C$7:$C$26="Good"))=0,"",SUMPRODUCT(($A$7:$A$26=1)*($C$7:$C$26="Good")*(F7:F26))/SUMPRODUCT(($A$7:$A$26=1)*($C$7:$C$26="Good"))) | G33: =IF(SUMPRODUCT(($A$7:$A$26=1)*($C$7:$C$26="Good"))=0,"",SUMPRODUCT(($A$7:$A$26=1)*($C$7:$C$26="Good")*(G7:G26))/SUMPRODUCT(($A$7:$A$26=1)*($C$7:$C$26="Good"))) | H33: =IF(SUMPRODUCT(($A$7:$A$26=1)*($C$7:$C$26="Good"))=0,"",SUMPRODUCT(($A$7:$A$26=1)*($C$7:$C$26="Good")*(H7:H26))/SUMPRODUCT(($A$7:$A$26=1)*($C$7:$C$26="Good"))) | I33: =IF(SUMPRODUCT(($A$7:$A$26=1)*($C$7:$C$26="Good"))=0,"",SUMPRODUCT(($A$7:$A$26=1)*($C$7:$C$26="Good")*(I7:I26))/SUMPRODUCT(($A$7:$A$26=1)*($C$7:$C$26="Good"))) | J33: =IF(SUMPRODUCT(($A$7:$A$26=1)*($C$7:$C$26="Good"))=0,"",SUMPRODUCT(($A$7:$A$26=1)*($C$7:$C$26="Good")*(J7:J26))/SUMPRODUCT(($A$7:$A$26=1)*($C$7:$C$26="Good"))) | K33: =IF(SUMPRODUCT(($A$7:$A$26=1)*($C$7:$C$26="Good"))=0,"",SUMPRODUCT(($A$7:$A$26=1)*($C$7:$C$26="Good")*(K7:K26))/SUMPRODUCT(($A$7:$A$26=1)*($C$7:$C$26="Good"))) | L33: =IF(SUMPRODUCT(($A$7:$A$26=1)*($C$7:$C$26="Good"))=0,"",SUMPRODUCT(($A$7:$A$26=1)*($C$7:$C$26="Good")*(L7:L26))/SUMPRODUCT(($A$7:$A$26=1)*($C$7:$C$26="Good"))) | ... AI33: =IF(SUMPRODUCT(($A$7:$A$26=1)*($C$7:$C$26="Good"))=0,"",SUMPRODUCT(($A$7:$A$26=1)*($C$7:$C$26="Good")*(AI7:AI26))/SUMPRODUCT(($A$7:$A$26=1)*($C$7:$C$26="Good"))) | AL33: Net score | AM33: =SUMPRODUCT(($E$6:$AI$6<=$B$3)*(E32:AI32))
AL34: Avg completion (Good) | AM34: =AVERAGEIF($E$6:$AI$6,"<="&$B$3,E33:AI33)

Sheet May
A1: May Habit Tracker
A2: Year: | B2: =Setup!$B$3 | C2: Month: | D2: May
A3: Days in month: | B3: =DAY(EOMONTH(DATE(Setup!$B$3,5,1),0))
E5: =TEXT(DATE(Setup!$B$3,5,1),"ddd") | F5: =TEXT(DATE(Setup!$B$3,5,2),"ddd") | G5: =TEXT(DATE(Setup!$B$3,5,3),"ddd") | H5: =TEXT(DATE(Setup!$B$3,5,4),"ddd") | I5: =TEXT(DATE(Setup!$B$3,5,5),"ddd") | J5: =TEXT(DATE(Setup!$B$3,5,6),"ddd") | K5: =TEXT(DATE(Setup!$B$3,5,7),"ddd") | L5: =TEXT(DATE(Setup!$B$3,5,8),"ddd") | M5: =TEXT(DATE(Setup!$B$3,5,9),"ddd") | N5: =TEXT(DATE(Setup!$B$3,5,10),"ddd") | O5: =TEXT(DATE(Setup!$B$3,5,11),"ddd") | P5: =TEXT(DATE(Setup!$B$3,5,12),"ddd") | Q5: =TEXT(DATE(Setup!$B$3,5,13),"ddd") | R5: =TEXT(DATE(Setup!$B$3,5,14),"ddd") | S5: =TEXT(DATE(Setup!$B$3,5,15),"ddd") | T5: =TEXT(DATE(Setup!$B$3,5,16),"ddd") | U5: =TEXT(DATE(Setup!$B$3,5,17),"ddd") | V5: =TEXT(DATE(Setup!$B$3,5,18),"ddd") | W5: =TEXT(DATE(Setup!$B$3,5,19),"ddd") | X5: =TEXT(DATE(Setup!$B$3,5,20),"ddd") | Y5: =TEXT(DATE(Setup!$B$3,5,21),"ddd") | Z5: =TEXT(DATE(Setup!$B$3,5,22),"ddd") | AA5: =TEXT(DATE(Setup!$B$3,5,23),"ddd") | AB5: =TEXT(DATE(Setup!$B$3,5,24),"ddd") | AC5: =TEXT(DATE(Setup!$B$3,5,25),"ddd") | AD5: =TEXT(DATE(Setup!$B$3,5,26),"ddd") | AE5: =TEXT(DATE(Setup!$B$3,5,27),"ddd") | AF5: =TEXT(DATE(Setup!$B$3,5,28),"ddd") | AG5: =TEXT(DATE(Setup!$B$3,5,29),"ddd") | AH5: =TEXT(DATE(Setup!$B$3,5,30),"ddd") | AI5: =TEXT(DATE(Setup!$B$3,5,31),"ddd")
A6: Active | B6: Habit | C6: Type | D6: Points | E6: 1 | F6: 2 | G6: 3 | H6: 4 | I6: 5 | J6: 6 | K6: 7 | L6: 8 | M6: 9 | N6: 10 | O6: 11 | P6: 12 | Q6: 13 | R6: 14 | S6: 15 | T6: 16 | U6: 17 | V6: 18 | W6: 19 | X6: 20 | Y6: 21 | Z6: 22 | AA6: 23 | AB6: 24 | AC6: 25 | AD6: 26 | AE6: 27 | AF6: 28 | AG6: 29 | AH6: 30 | AI6: 31 | AJ6: Total
A7: =Setup!D9 | B7: =Setup!A9 | C7: =Setup!B9 | D7: =Setup!E9 | AJ7: =IF($A7=1,SUMPRODUCT(($E$6:$AI$6<=$B$3)*(E7:AI7)),"")
A8: =Setup!D10 | B8: =Setup!A10 | C8: =Setup!B10 | D8: =Setup!E10 | AJ8: =IF($A8=1,SUMPRODUCT(($E$6:$AI$6<=$B$3)*(E8:AI8)),"")
A9: =Setup!D11 | B9: =Setup!A11 | C9: =Setup!B11 | D9: =Setup!E11 | AJ9: =IF($A9=1,SUMPRODUCT(($E$6:$AI$6<=$B$3)*(E9:AI9)),"")
A10: =Setup!D12 | B10: =Setup!A12 | C10: =Setup!B12 | D10: =Setup!E12 | AJ10: =IF($A10=1,SUMPRODUCT(($E$6:$AI$6<=$B$3)*(E10:AI10)),"")
A11: =Setup!D13 | B11: =Setup!A13 | C11: =Setup!B13 | D11: =Setup!E13 | AJ11: =IF($A11=1,SUMPRODUCT(($E$6:$AI$6<=$B$3)*(E11:AI11)),"")
A12: =Setup!D14 | B12: =Setup!A14 | C12: =Setup!B14 | D12: =Setup!E14 | AJ12: =IF($A12=1,SUMPRODUCT(($E$6:$AI$6<=$B$3)*(E12:AI12)),"")
A13: =Setup!D15 | B13: =Setup!A15 | C13: =Setup!B15 | D13: =Setup!E15 | AJ13: =IF($A13=1,SUMPRODUCT(($E$6:$AI$6<=$B$3)*(E13:AI13)),"")
A14: =Setup!D16 | B14: =Setup!A16 | C14: =Setup!B16 | D14: =Setup!E16 | AJ14: =IF($A14=1,SUMPRODUCT(($E$6:$AI$6<=$B$3)*(E14:AI14)),"")
A15: =Setup!D17 | B15: =Setup!A17 | C15: =Setup!B17 | D15: =Setup!E17 | AJ15: =IF($A15=1,SUMPRODUCT(($E$6:$AI$6<=$B$3)*(E15:AI15)),"")
A16: =Setup!D18 | B16: =Setup!A18 | C16: =Setup!B18 | D16: =Setup!E18 | AJ16: =IF($A16=1,SUMPRODUCT(($E$6:$AI$6<=$B$3)*(E16:AI16)),"")
A17: =Setup!D19 | B17: =Setup!A19 | C17: =Setup!B19 | D17: =Setup!E19 | AJ17: =IF($A17=1,SUMPRODUCT(($E$6:$AI$6<=$B$3)*(E17:AI17)),"")
A18: =Setup!D20 | B18: =Setup!A20 | C18: =Setup!B20 | D18: =Setup!E20 | AJ18: =IF($A18=1,SUMPRODUCT(($E$6:$AI$6<=$B$3)*(E18:AI18)),"")
... A26: =Setup!D28 | B26: =Setup!A28 | C26: =Setup!B28 | D26: =Setup!E28 | AJ26: =IF($A26=1,SUMPRODUCT(($E$6:$AI$6<=$B$3)*(E26:AI26)),"")
A29: Daily summary
A30: Good habits done | E30: =SUMPRODUCT(($A$7:$A$26=1)*($C$7:$C$26="Good")*(E7:E26)) | F30: =SUMPRODUCT(($A$7:$A$26=1)*($C$7:$C$26="Good")*(F7:F26)) | G30: =SUMPRODUCT(($A$7:$A$26=1)*($C$7:$C$26="Good")*(G7:G26)) | H30: =SUMPRODUCT(($A$7:$A$26=1)*($C$7:$C$26="Good")*(H7:H26)) | I30: =SUMPRODUCT(($A$7:$A$26=1)*($C$7:$C$26="Good")*(I7:I26)) | J30: =SUMPRODUCT(($A$7:$A$26=1)*($C$7:$C$26="Good")*(J7:J26)) | K30: =SUMPRODUCT(($A$7:$A$26=1)*($C$7:$C$26="Good")*(K7:K26)) | L30: =SUMPRODUCT(($A$7:$A$26=1)*($C$7:$C$26="Good")*(L7:L26)) | ... AI30: =SUMPRODUCT(($A$7:$A$26=1)*($C$7:$C$26="Good")*(AI7:AI26)) | AL30: Monthly totals
A31: Bad habits happened | E31: =SUMPRODUCT(($A$7:$A$26=1)*($C$7:$C$26="Bad")*(E7:E26)) | F31: =SUMPRODUCT(($A$7:$A$26=1)*($C$7:$C$26="Bad")*(F7:F26)) | G31: =SUMPRODUCT(($A$7:$A$26=1)*($C$7:$C$26="Bad")*(G7:G26)) | H31: =SUMPRODUCT(($A$7:$A$26=1)*($C$7:$C$26="Bad")*(H7:H26)) | I31: =SUMPRODUCT(($A$7:$A$26=1)*($C$7:$C$26="Bad")*(I7:I26)) | J31: =SUMPRODUCT(($A$7:$A$26=1)*($C$7:$C$26="Bad")*(J7:J26)) | K31: =SUMPRODUCT(($A$7:$A$26=1)*($C$7:$C$26="Bad")*(K7:K26)) | L31: =SUMPRODUCT(($A$7:$A$26=1)*($C$7:$C$26="Bad")*(L7:L26)) | ... AI31: =SUMPRODUCT(($A$7:$A$26=1)*($C$7:$C$26="Bad")*(AI7:AI26)) | AL31: Good done | AM31: =SUMPRODUCT(($E$6:$AI$6<=$B$3)*(E30:AI30))
A32: Net score | E32: =SUMPRODUCT(($A$7:$A$26=1)*($D$7:$D$26)*(E7:E26)) | F32: =SUMPRODUCT(($A$7:$A$26=1)*($D$7:$D$26)*(F7:F26)) | G32: =SUMPRODUCT(($A$7:$A$26=1)*($D$7:$D$26)*(G7:G26)) | H32: =SUMPRODUCT(($A$7:$A$26=1)*($D$7:$D$26)*(H7:H26)) | I32: =SUMPRODUCT(($A$7:$A$26=1)*($D$7:$D$26)*(I7:I26)) | J32: =SUMPRODUCT(($A$7:$A$26=1)*($D$7:$D$26)*(J7:J26)) | K32: =SUMPRODUCT(($A$7:$A$26=1)*($D$7:$D$26)*(K7:K26)) | L32: =SUMPRODUCT(($A$7:$A$26=1)*($D$7:$D$26)*(L7:L26)) | ... AI32: =SUMPRODUCT(($A$7:$A$26=1)*($D$7:$D$26)*(AI7:AI26)) | AL32: Bad happened | AM32: =SUMPRODUCT(($E$6:$AI$6<=$B$3)*(E31:AI31))
A33: Completion % (Good only) | E33: =IF(SUMPRODUCT(($A$7:$A$26=1)*($C$7:$C$26="Good"))=0,"",SUMPRODUCT(($A$7:$A$26=1)*($C$7:$C$26="Good")*(E7:E26))/SUMPRODUCT(($A$7:$A$26=1)*($C$7:$C$26="Good"))) | F33: =IF(SUMPRODUCT(($A$7:$A$26=1)*($C$7:$C$26="Good"))=0,"",SUMPRODUCT(($A$7:$A$26=1)*($C$7:$C$26="Good")*(F7:F26))/SUMPRODUCT(($A$7:$A$26=1)*($C$7:$C$26="Good"))) | G33: =IF(SUMPRODUCT(($A$7:$A$26=1)*($C$7:$C$26="Good"))=0,"",SUMPRODUCT(($A$7:$A$26=1)*($C$7:$C$26="Good")*(G7:G26))/SUMPRODUCT(($A$7:$A$26=1)*($C$7:$C$26="Good"))) | H33: =IF(SUMPRODUCT(($A$7:$A$26=1)*($C$7:$C$26="Good"))=0,"",SUMPRODUCT(($A$7:$A$26=1)*($C$7:$C$26="Good")*(H7:H26))/SUMPRODUCT(($A$7:$A$26=1)*($C$7:$C$26="Good"))) | I33: =IF(SUMPRODUCT(($A$7:$A$26=1)*($C$7:$C$26="Good"))=0,"",SUMPRODUCT(($A$7:$A$26=1)*($C$7:$C$26="Good")*(I7:I26))/SUMPRODUCT(($A$7:$A$26=1)*($C$7:$C$26="Good"))) | J33: =IF(SUMPRODUCT(($A$7:$A$26=1)*($C$7:$C$26="Good"))=0,"",SUMPRODUCT(($A$7:$A$26=1)*($C$7:$C$26="Good")*(J7:J26))/SUMPRODUCT(($A$7:$A$26=1)*($C$7:$C$26="Good"))) | K33: =IF(SUMPRODUCT(($A$7:$A$26=1)*($C$7:$C$26="Good"))=0,"",SUMPRODUCT(($A$7:$A$26=1)*($C$7:$C$26="Good")*(K7:K26))/SUMPRODUCT(($A$7:$A$26=1)*($C$7:$C$26="Good"))) | L33: =IF(SUMPRODUCT(($A$7:$A$26=1)*($C$7:$C$26="Good"))=0,"",SUMPRODUCT(($A$7:$A$26=1)*($C$7:$C$26="Good")*(L7:L26))/SUMPRODUCT(($A$7:$A$26=1)*($C$7:$C$26="Good"))) | ... AI33: =IF(SUMPRODUCT(($A$7:$A$26=1)*($C$7:$C$26="Good"))=0,"",SUMPRODUCT(($A$7:$A$26=1)*($C$7:$C$26="Good")*(AI7:AI26))/SUMPRODUCT(($A$7:$A$26=1)*($C$7:$C$26="Good"))) | AL33: Net score | AM33: =SUMPRODUCT(($E$6:$AI$6<=$B$3)*(E32:AI32))
AL34: Avg completion (Good) | AM34: =AVERAGEIF($E$6:$AI$6,"<="&$B$3,E33:AI33)

Sheet Jun
A1: Jun Habit Tracker
A2: Year: | B2: =Setup!$B$3 | C2: Month: | D2: Jun
A3: Days in month: | B3: =DAY(EOMONTH(DATE(Setup!$B$3,6,1),0))
E5: =TEXT(DATE(Setup!$B$3,6,1),"ddd") | F5: =TEXT(DATE(Setup!$B$3,6,2),"ddd") | G5: =TEXT(DATE(Setup!$B$3,6,3),"ddd") | H5: =TEXT(DATE(Setup!$B$3,6,4),"ddd") | I5: =TEXT(DATE(Setup!$B$3,6,5),"ddd") | J5: =TEXT(DATE(Setup!$B$3,6,6),"ddd") | K5: =TEXT(DATE(Setup!$B$3,6,7),"ddd") | L5: =TEXT(DATE(Setup!$B$3,6,8),"ddd") | M5: =TEXT(DATE(Setup!$B$3,6,9),"ddd") | N5: =TEXT(DATE(Setup!$B$3,6,10),"ddd") | O5: =TEXT(DATE(Setup!$B$3,6,11),"ddd") | P5: =TEXT(DATE(Setup!$B$3,6,12),"ddd") | Q5: =TEXT(DATE(Setup!$B$3,6,13),"ddd") | R5: =TEXT(DATE(Setup!$B$3,6,14),"ddd") | S5: =TEXT(DATE(Setup!$B$3,6,15),"ddd") | T5: =TEXT(DATE(Setup!$B$3,6,16),"ddd") | U5: =TEXT(DATE(Setup!$B$3,6,17),"ddd") | V5: =TEXT(DATE(Setup!$B$3,6,18),"ddd") | W5: =TEXT(DATE(Setup!$B$3,6,19),"ddd") | X5: =TEXT(DATE(Setup!$B$3,6,20),"ddd") | Y5: =TEXT(DATE(Setup!$B$3,6,21),"ddd") | Z5: =TEXT(DATE(Setup!$B$3,6,22),"ddd") | AA5: =TEXT(DATE(Setup!$B$3,6,23),"ddd") | AB5: =TEXT(DATE(Setup!$B$3,6,24),"ddd") | AC5: =TEXT(DATE(Setup!$B$3,6,25),"ddd") | AD5: =TEXT(DATE(Setup!$B$3,6,26),"ddd") | AE5: =TEXT(DATE(Setup!$B$3,6,27),"ddd") | AF5: =TEXT(DATE(Setup!$B$3,6,28),"ddd") | AG5: =TEXT(DATE(Setup!$B$3,6,29),"ddd") | AH5: =TEXT(DATE(Setup!$B$3,6,30),"ddd") | AI5: =TEXT(DATE(Setup!$B$3,6,31),"ddd")
A6: Active | B6: Habit | C6: Type | D6: Points | E6: 1 | F6: 2 | G6: 3 | H6: 4 | I6: 5 | J6: 6 | K6: 7 | L6: 8 | M6: 9 | N6: 10 | O6: 11 | P6: 12 | Q6: 13 | R6: 14 | S6: 15 | T6: 16 | U6: 17 | V6: 18 | W6: 19 | X6: 20 | Y6: 21 | Z6: 22 | AA6: 23 | AB6: 24 | AC6: 25 | AD6: 26 | AE6: 27 | AF6: 28 | AG6: 29 | AH6: 30 | AI6: 31 | AJ6: Total
A7: =Setup!D9 | B7: =Setup!A9 | C7: =Setup!B9 | D7: =Setup!E9 | AJ7: =IF($A7=1,SUMPRODUCT(($E$6:$AI$6<=$B$3)*(E7:AI7)),"")
A8: =Setup!D10 | B8: =Setup!A10 | C8: =Setup!B10 | D8: =Setup!E10 | AJ8: =IF($A8=1,SUMPRODUCT(($E$6:$AI$6<=$B$3)*(E8:AI8)),"")
A9: =Setup!D11 | B9: =Setup!A11 | C9: =Setup!B11 | D9: =Setup!E11 | AJ9: =IF($A9=1,SUMPRODUCT(($E$6:$AI$6<=$B$3)*(E9:AI9)),"")
A10: =Setup!D12 | B10: =Setup!A12 | C10: =Setup!B12 | D10: =Setup!E12 | AJ10: =IF($A10=1,SUMPRODUCT(($E$6:$AI$6<=$B$3)*(E10:AI10)),"")
A11: =Setup!D13 | B11: =Setup!A13 | C11: =Setup!B13 | D11: =Setup!E13 | AJ11: =IF($A11=1,SUMPRODUCT(($E$6:$AI$6<=$B$3)*(E11:AI11)),"")
A12: =Setup!D14 | B12: =Setup!A14 | C12: =Setup!B14 | D12: =Setup!E14 | AJ12: =IF($A12=1,SUMPRODUCT(($E$6:$AI$6<=$B$3)*(E12:AI12)),"")
A13: =Setup!D15 | B13: =Setup!A15 | C13: =Setup!B15 | D13: =Setup!E15 | AJ13: =IF($A13=1,SUMPRODUCT(($E$6:$AI$6<=$B$3)*(E13:AI13)),"")
A14: =Setup!D16 | B14: =Setup!A16 | C14: =Setup!B16 | D14: =Setup!E16 | AJ14: =IF($A14=1,SUMPRODUCT(($E$6:$AI$6<=$B$3)*(E14:AI14)),"")
A15: =Setup!D17 | B15: =Setup!A17 | C15: =Setup!B17 | D15: =Setup!E17 | AJ15: =IF($A15=1,SUMPRODUCT(($E$6:$AI$6<=$B$3)*(E15:AI15)),"")
A16: =Setup!D18 | B16: =Setup!A18 | C16: =Setup!B18 | D16: =Setup!E18 | AJ16: =IF($A16=1,SUMPRODUCT(($E$6:$AI$6<=$B$3)*(E16:AI16)),"")
A17: =Setup!D19 | B17: =Setup!A19 | C17: =Setup!B19 | D17: =Setup!E19 | AJ17: =IF($A17=1,SUMPRODUCT(($E$6:$AI$6<=$B$3)*(E17:AI17)),"")
A18: =Setup!D20 | B18: =Setup!A20 | C18: =Setup!B20 | D18: =Setup!E20 | AJ18: =IF($A18=1,SUMPRODUCT(($E$6:$AI$6<=$B$3)*(E18:AI18)),"")
... A26: =Setup!D28 | B26: =Setup!A28 | C26: =Setup!B28 | D26: =Setup!E28 | AJ26: =IF($A26=1,SUMPRODUCT(($E$6:$AI$6<=$B$3)*(E26:AI26)),"")
A29: Daily summary
A30: Good habits done | E30: =SUMPRODUCT(($A$7:$A$26=1)*($C$7:$C$26="Good")*(E7:E26)) | F30: =SUMPRODUCT(($A$7:$A$26=1)*($C$7:$C$26="Good")*(F7:F26)) | G30: =SUMPRODUCT(($A$7:$A$26=1)*($C$7:$C$26="Good")*(G7:G26)) | H30: =SUMPRODUCT(($A$7:$A$26=1)*($C$7:$C$26="Good")*(H7:H26)) | I30: =SUMPRODUCT(($A$7:$A$26=1)*($C$7:$C$26="Good")*(I7:I26)) | J30: =SUMPRODUCT(($A$7:$A$26=1)*($C$7:$C$26="Good")*(J7:J26)) | K30: =SUMPRODUCT(($A$7:$A$26=1)*($C$7:$C$26="Good")*(K7:K26)) | L30: =SUMPRODUCT(($A$7:$A$26=1)*($C$7:$C$26="Good")*(L7:L26)) | ... AI30: =SUMPRODUCT(($A$7:$A$26=1)*($C$7:$C$26="Good")*(AI7:AI26)) | AL30: Monthly totals
A31: Bad habits happened | E31: =SUMPRODUCT(($A$7:$A$26=1)*($C$7:$C$26="Bad")*(E7:E26)) | F31: =SUMPRODUCT(($A$7:$A$26=1)*($C$7:$C$26="Bad")*(F7:F26)) | G31: =SUMPRODUCT(($A$7:$A$26=1)*($C$7:$C$26="Bad")*(G7:G26)) | H31: =SUMPRODUCT(($A$7:$A$26=1)*($C$7:$C$26="Bad")*(H7:H26)) | I31: =SUMPRODUCT(($A$7:$A$26=1)*($C$7:$C$26="Bad")*(I7:I26)) | J31: =SUMPRODUCT(($A$7:$A$26=1)*($C$7:$C$26="Bad")*(J7:J26)) | K31: =SUMPRODUCT(($A$7:$A$26=1)*($C$7:$C$26="Bad")*(K7:K26)) | L31: =SUMPRODUCT(($A$7:$A$26=1)*($C$7:$C$26="Bad")*(L7:L26)) | ... AI31: =SUMPRODUCT(($A$7:$A$26=1)*($C$7:$C$26="Bad")*(AI7:AI26)) | AL31: Good done | AM31: =SUMPRODUCT(($E$6:$AI$6<=$B$3)*(E30:AI30))
A32: Net score | E32: =SUMPRODUCT(($A$7:$A$26=1)*($D$7:$D$26)*(E7:E26)) | F32: =SUMPRODUCT(($A$7:$A$26=1)*($D$7:$D$26)*(F7:F26)) | G32: =SUMPRODUCT(($A$7:$A$26=1)*($D$7:$D$26)*(G7:G26)) | H32: =SUMPRODUCT(($A$7:$A$26=1)*($D$7:$D$26)*(H7:H26)) | I32: =SUMPRODUCT(($A$7:$A$26=1)*($D$7:$D$26)*(I7:I26)) | J32: =SUMPRODUCT(($A$7:$A$26=1)*($D$7:$D$26)*(J7:J26)) | K32: =SUMPRODUCT(($A$7:$A$26=1)*($D$7:$D$26)*(K7:K26)) | L32: =SUMPRODUCT(($A$7:$A$26=1)*($D$7:$D$26)*(L7:L26)) | ... AI32: =SUMPRODUCT(($A$7:$A$26=1)*($D$7:$D$26)*(AI7:AI26)) | AL32: Bad happened | AM32: =SUMPRODUCT(($E$6:$AI$6<=$B$3)*(E31:AI31))
A33: Completion % (Good only) | E33: =IF(SUMPRODUCT(($A$7:$A$26=1)*($C$7:$C$26="Good"))=0,"",SUMPRODUCT(($A$7:$A$26=1)*($C$7:$C$26="Good")*(E7:E26))/SUMPRODUCT(($A$7:$A$26=1)*($C$7:$C$26="Good"))) | F33: =IF(SUMPRODUCT(($A$7:$A$26=1)*($C$7:$C$26="Good"))=0,"",SUMPRODUCT(($A$7:$A$26=1)*($C$7:$C$26="Good")*(F7:F26))/SUMPRODUCT(($A$7:$A$26=1)*($C$7:$C$26="Good"))) | G33: =IF(SUMPRODUCT(($A$7:$A$26=1)*($C$7:$C$26="Good"))=0,"",SUMPRODUCT(($A$7:$A$26=1)*($C$7:$C$26="Good")*(G7:G26))/SUMPRODUCT(($A$7:$A$26=1)*($C$7:$C$26="Good"))) | H33: =IF(SUMPRODUCT(($A$7:$A$26=1)*($C$7:$C$26="Good"))=0,"",SUMPRODUCT(($A$7:$A$26=1)*($C$7:$C$26="Good")*(H7:H26))/SUMPRODUCT(($A$7:$A$26=1)*($C$7:$C$26="Good"))) | I33: =IF(SUMPRODUCT(($A$7:$A$26=1)*($C$7:$C$26="Good"))=0,"",SUMPRODUCT(($A$7:$A$26=1)*($C$7:$C$26="Good")*(I7:I26))/SUMPRODUCT(($A$7:$A$26=1)*($C$7:$C$26="Good"))) | J33: =IF(SUMPRODUCT(($A$7:$A$26=1)*($C$7:$C$26="Good"))=0,"",SUMPRODUCT(($A$7:$A$26=1)*($C$7:$C$26="Good")*(J7:J26))/SUMPRODUCT(($A$7:$A$26=1)*($C$7:$C$26="Good"))) | K33: =IF(SUMPRODUCT(($A$7:$A$26=1)*($C$7:$C$26="Good"))=0,"",SUMPRODUCT(($A$7:$A$26=1)*($C$7:$C$26="Good")*(K7:K26))/SUMPRODUCT(($A$7:$A$26=1)*($C$7:$C$26="Good"))) | L33: =IF(SUMPRODUCT(($A$7:$A$26=1)*($C$7:$C$26="Good"))=0,"",SUMPRODUCT(($A$7:$A$26=1)*($C$7:$C$26="Good")*(L7:L26))/SUMPRODUCT(($A$7:$A$26=1)*($C$7:$C$26="Good"))) | ... AI33: =IF(SUMPRODUCT(($A$7:$A$26=1)*($C$7:$C$26="Good"))=0,"",SUMPRODUCT(($A$7:$A$26=1)*($C$7:$C$26="Good")*(AI7:AI26))/SUMPRODUCT(($A$7:$A$26=1)*($C$7:$C$26="Good"))) | AL33: Net score | AM33: =SUMPRODUCT(($E$6:$AI$6<=$B$3)*(E32:AI32))
AL34: Avg completion (Good) | AM34: =AVERAGEIF($E$6:$AI$6,"<="&$B$3,E33:AI33)

Sheet Jul
A1: Jul Habit Tracker
A2: Year: | B2: =Setup!$B$3 | C2: Month: | D2: Jul
A3: Days in month: | B3: =DAY(EOMONTH(DATE(Setup!$B$3,7,1),0))
E5: =TEXT(DATE(Setup!$B$3,7,1),"ddd") | F5: =TEXT(DATE(Setup!$B$3,7,2),"ddd") | G5: =TEXT(DATE(Setup!$B$3,7,3),"ddd") | H5: =TEXT(DATE(Setup!$B$3,7,4),"ddd") | I5: =TEXT(DATE(Setup!$B$3,7,5),"ddd") | J5: =TEXT(DATE(Setup!$B$3,7,6),"ddd") | K5: =TEXT(DATE(Setup!$B$3,7,7),"ddd") | L5: =TEXT(DATE(Setup!$B$3,7,8),"ddd") | M5: =TEXT(DATE(Setup!$B$3,7,9),"ddd") | N5: =TEXT(DATE(Setup!$B$3,7,10),"ddd") | O5: =TEXT(DATE(Setup!$B$3,7,11),"ddd") | P5: =TEXT(DATE(Setup!$B$3,7,12),"ddd") | Q5: =TEXT(DATE(Setup!$B$3,7,13),"ddd") | R5: =TEXT(DATE(Setup!$B$3,7,14),"ddd") | S5: =TEXT(DATE(Setup!$B$3,7,15),"ddd") | T5: =TEXT(DATE(Setup!$B$3,7,16),"ddd") | U5: =TEXT(DATE(Setup!$B$3,7,17),"ddd") | V5: =TEXT(DATE(Setup!$B$3,7,18),"ddd") | W5: =TEXT(DATE(Setup!$B$3,7,19),"ddd") | X5: =TEXT(DATE(Setup!$B$3,7,20),"ddd") | Y5: =TEXT(DATE(Setup!$B$3,7,21),"ddd") | Z5: =TEXT(DATE(Setup!$B$3,7,22),"ddd") | AA5: =TEXT(DATE(Setup!$B$3,7,23),"ddd") | AB5: =TEXT(DATE(Setup!$B$3,7,24),"ddd") | AC5: =TEXT(DATE(Setup!$B$3,7,25),"ddd") | AD5: =TEXT(DATE(Setup!$B$3,7,26),"ddd") | AE5: =TEXT(DATE(Setup!$B$3,7,27),"ddd") | AF5: =TEXT(DATE(Setup!$B$3,7,28),"ddd") | AG5: =TEXT(DATE(Setup!$B$3,7,29),"ddd") | AH5: =TEXT(DATE(Setup!$B$3,7,30),"ddd") | AI5: =TEXT(DATE(Setup!$B$3,7,31),"ddd")
A6: Active | B6: Habit | C6: Type | D6: Points | E6: 1 | F6: 2 | G6: 3 | H6: 4 | I6: 5 | J6: 6 | K6: 7 | L6: 8 | M6: 9 | N6: 10 | O6: 11 | P6: 12 | Q6: 13 | R6: 14 | S6: 15 | T6: 16 | U6: 17 | V6: 18 | W6: 19 | X6: 20 | Y6: 21 | Z6: 22 | AA6: 23 | AB6: 24 | AC6: 25 | AD6: 26 | AE6: 27 | AF6: 28 | AG6: 29 | AH6: 30 | AI6: 31 | AJ6: Total
A7: =Setup!D9 | B7: =Setup!A9 | C7: =Setup!B9 | D7: =Setup!E9 | AJ7: =IF($A7=1,SUMPRODUCT(($E$6:$AI$6<=$B$3)*(E7:AI7)),"")
A8: =Setup!D10 | B8: =Setup!A10 | C8: =Setup!B10 | D8: =Setup!E10 | AJ8: =IF($A8=1,SUMPRODUCT(($E$6:$AI$6<=$B$3)*(E8:AI8)),"")
A9: =Setup!D11 | B9: =Setup!A11 | C9: =Setup!B11 | D9: =Setup!E11 | AJ9: =IF($A9=1,SUMPRODUCT(($E$6:$AI$6<=$B$3)*(E9:AI9)),"")
A10: =Setup!D12 | B10: =Setup!A12 | C10: =Setup!B12 | D10: =Setup!E12 | AJ10: =IF($A10=1,SUMPRODUCT(($E$6:$AI$6<=$B$3)*(E10:AI10)),"")
A11: =Setup!D13 | B11: =Setup!A13 | C11: =Setup!B13 | D11: =Setup!E13 | AJ11: =IF($A11=1,SUMPRODUCT(($E$6:$AI$6<=$B$3)*(E11:AI11)),"")
A12: =Setup!D14 | B12: =Setup!A14 | C12: =Setup!B14 | D12: =Setup!E14 | AJ12: =IF($A12=1,SUMPRODUCT(($E$6:$AI$6<=$B$3)*(E12:AI12)),"")
A13: =Setup!D15 | B13: =Setup!A15 | C13: =Setup!B15 | D13: =Setup!E15 | AJ13: =IF($A13=1,SUMPRODUCT(($E$6:$AI$6<=$B$3)*(E13:AI13)),"")
A14: =Setup!D16 | B14: =Setup!A16 | C14: =Setup!B16 | D14: =Setup!E16 | AJ14: =IF($A14=1,SUMPRODUCT(($E$6:$AI$6<=$B$3)*(E14:AI14)),"")
A15: =Setup!D17 | B15: =Setup!A17 | C15: =Setup!B17 | D15: =Setup!E17 | AJ15: =IF($A15=1,SUMPRODUCT(($E$6:$AI$6<=$B$3)*(E15:AI15)),"")
A16: =Setup!D18 | B16: =Setup!A18 | C16: =Setup!B18 | D16: =Setup!E18 | AJ16: =IF($A16=1,SUMPRODUCT(($E$6:$AI$6<=$B$3)*(E16:AI16)),"")
A17: =Setup!D19 | B17: =Setup!A19 | C17: =Setup!B19 | D17: =Setup!E19 | AJ17: =IF($A17=1,SUMPRODUCT(($E$6:$AI$6<=$B$3)*(E17:AI17)),"")
A18: =Setup!D20 | B18: =Setup!A20 | C18: =Setup!B20 | D18: =Setup!E20 | AJ18: =IF($A18=1,SUMPRODUCT(($E$6:$AI$6<=$B$3)*(E18:AI18)),"")
... A26: =Setup!D28 | B26: =Setup!A28 | C26: =Setup!B28 | D26: =Setup!E28 | AJ26: =IF($A26=1,SUMPRODUCT(($E$6:$AI$6<=$B$3)*(E26:AI26)),"")
A29: Daily summary
A30: Good habits done | E30: =SUMPRODUCT(($A$7:$A$26=1)*($C$7:$C$26="Good")*(E7:E26)) | F30: =SUMPRODUCT(($A$7:$A$26=1)*($C$7:$C$26="Good")*(F7:F26)) | G30: =SUMPRODUCT(($A$7:$A$26=1)*($C$7:$C$26="Good")*(G7:G26)) | H30: =SUMPRODUCT(($A$7:$A$26=1)*($C$7:$C$26="Good")*(H7:H26)) | I30: =SUMPRODUCT(($A$7:$A$26=1)*($C$7:$C$26="Good")*(I7:I26)) | J30: =SUMPRODUCT(($A$7:$A$26=1)*($C$7:$C$26="Good")*(J7:J26)) | K30: =SUMPRODUCT(($A$7:$A$26=1)*($C$7:$C$26="Good")*(K7:K26)) | L30: =SUMPRODUCT(($A$7:$A$26=1)*($C$7:$C$26="Good")*(L7:L26)) | ... AI30: =SUMPRODUCT(($A$7:$A$26=1)*($C$7:$C$26="Good")*(AI7:AI26)) | AL30: Monthly totals
A31: Bad habits happened | E31: =SUMPRODUCT(($A$7:$A$26=1)*($C$7:$C$26="Bad")*(E7:E26)) | F31: =SUMPRODUCT(($A$7:$A$26=1)*($C$7:$C$26="Bad")*(F7:F26)) | G31: =SUMPRODUCT(($A$7:$A$26=1)*($C$7:$C$26="Bad")*(G7:G26)) | H31: =SUMPRODUCT(($A$7:$A$26=1)*($C$7:$C$26="Bad")*(H7:H26)) | I31: =SUMPRODUCT(($A$7:$A$26=1)*($C$7:$C$26="Bad")*(I7:I26)) | J31: =SUMPRODUCT(($A$7:$A$26=1)*($C$7:$C$26="Bad")*(J7:J26)) | K31: =SUMPRODUCT(($A$7:$A$26=1)*($C$7:$C$26="Bad")*(K7:K26)) | L31: =SUMPRODUCT(($A$7:$A$26=1)*($C$7:$C$26="Bad")*(L7:L26)) | ... AI31: =SUMPRODUCT(($A$7:$A$26=1)*($C$7:$C$26="Bad")*(AI7:AI26)) | AL31: Good done | AM31: =SUMPRODUCT(($E$6:$AI$6<=$B$3)*(E30:AI30))
A32: Net score | E32: =SUMPRODUCT(($A$7:$A$26=1)*($D$7:$D$26)*(E7:E26)) | F32: =SUMPRODUCT(($A$7:$A$26=1)*($D$7:$D$26)*(F7:F26)) | G32: =SUMPRODUCT(($A$7:$A$26=1)*($D$7:$D$26)*(G7:G26)) | H32: =SUMPRODUCT(($A$7:$A$26=1)*($D$7:$D$26)*(H7:H26)) | I32: =SUMPRODUCT(($A$7:$A$26=1)*($D$7:$D$26)*(I7:I26)) | J32: =SUMPRODUCT(($A$7:$A$26=1)*($D$7:$D$26)*(J7:J26)) | K32: =SUMPRODUCT(($A$7:$A$26=1)*($D$7:$D$26)*(K7:K26)) | L32: =SUMPRODUCT(($A$7:$A$26=1)*($D$7:$D$26)*(L7:L26)) | ... AI32: =SUMPRODUCT(($A$7:$A$26=1)*($D$7:$D$26)*(AI7:AI26)) | AL32: Bad happened | AM32: =SUMPRODUCT(($E$6:$AI$6<=$B$3)*(E31:AI31))
A33: Completion % (Good only) | E33: =IF(SUMPRODUCT(($A$7:$A$26=1)*($C$7:$C$26="Good"))=0,"",SUMPRODUCT(($A$7:$A$26=1)*($C$7:$C$26="Good")*(E7:E26))/SUMPRODUCT(($A$7:$A$26=1)*($C$7:$C$26="Good"))) | F33: =IF(SUMPRODUCT(($A$7:$A$26=1)*($C$7:$C$26="Good"))=0,"",SUMPRODUCT(($A$7:$A$26=1)*($C$7:$C$26="Good")*(F7:F26))/SUMPRODUCT(($A$7:$A$26=1)*($C$7:$C$26="Good"))) | G33: =IF(SUMPRODUCT(($A$7:$A$26=1)*($C$7:$C$26="Good"))=0,"",SUMPRODUCT(($A$7:$A$26=1)*($C$7:$C$26="Good")*(G7:G26))/SUMPRODUCT(($A$7:$A$26=1)*($C$7:$C$26="Good"))) | H33: =IF(SUMPRODUCT(($A$7:$A$26=1)*($C$7:$C$26="Good"))=0,"",SUMPRODUCT(($A$7:$A$26=1)*($C$7:$C$26="Good")*(H7:H26))/SUMPRODUCT(($A$7:$A$26=1)*($C$7:$C$26="Good"))) | I33: =IF(SUMPRODUCT(($A$7:$A$26=1)*($C$7:$C$26="Good"))=0,"",SUMPRODUCT(($A$7:$A$26=1)*($C$7:$C$26="Good")*(I7:I26))/SUMPRODUCT(($A$7:$A$26=1)*($C$7:$C$26="Good"))) | J33: =IF(SUMPRODUCT(($A$7:$A$26=1)*($C$7:$C$26="Good"))=0,"",SUMPRODUCT(($A$7:$A$26=1)*($C$7:$C$26="Good")*(J7:J26))/SUMPRODUCT(($A$7:$A$26=1)*($C$7:$C$26="Good"))) | K33: =IF(SUMPRODUCT(($A$7:$A$26=1)*($C$7:$C$26="Good"))=0,"",SUMPRODUCT(($A$7:$A$26=1)*($C$7:$C$26="Good")*(K7:K26))/SUMPRODUCT(($A$7:$A$26=1)*($C$7:$C$26="Good"))) | L33: =IF(SUMPRODUCT(($A$7:$A$26=1)*($C$7:$C$26="Good"))=0,"",SUMPRODUCT(($A$7:$A$26=1)*($C$7:$C$26="Good")*(L7:L26))/SUMPRODUCT(($A$7:$A$26=1)*($C$7:$C$26="Good"))) | ... AI33: =IF(SUMPRODUCT(($A$7:$A$26=1)*($C$7:$C$26="Good"))=0,"",SUMPRODUCT(($A$7:$A$26=1)*($C$7:$C$26="Good")*(AI7:AI26))/SUMPRODUCT(($A$7:$A$26=1)*($C$7:$C$26="Good"))) | AL33: Net score | AM33: =SUMPRODUCT(($E$6:$AI$6<=$B$3)*(E32:AI32))
AL34: Avg completion (Good) | AM34: =AVERAGEIF($E$6:$AI$6,"<="&$B$3,E33:AI33)

Sheet Aug
A1: Aug Habit Tracker
A2: Year: | B2: =Setup!$B$3 | C2: Month: | D2: Aug
A3: Days in month: | B3: =DAY(EOMONTH(DATE(Setup!$B$3,8,1),0))
E5: =TEXT(DATE(Setup!$B$3,8,1),"ddd") | F5: =TEXT(DATE(Setup!$B$3,8,2),"ddd") | G5: =TEXT(DATE(Setup!$B$3,8,3),"ddd") | H5: =TEXT(DATE(Setup!$B$3,8,4),"ddd") | I5: =TEXT(DATE(Setup!$B$3,8,5),"ddd") | J5: =TEXT(DATE(Setup!$B$3,8,6),"ddd") | K5: =TEXT(DATE(Setup!$B$3,8,7),"ddd") | L5: =TEXT(DATE(Setup!$B$3,8,8),"ddd") | M5: =TEXT(DATE(Setup!$B$3,8,9),"ddd") | N5: =TEXT(DATE(Setup!$B$3,8,10),"ddd") | O5: =TEXT(DATE(Setup!$B$3,8,11),"ddd") | P5: =TEXT(DATE(Setup!$B$3,8,12),"ddd") | Q5: =TEXT(DATE(Setup!$B$3,8,13),"ddd") | R5: =TEXT(DATE(Setup!$B$3,8,14),"ddd") | S5: =TEXT(DATE(Setup!$B$3,8,15),"ddd") | T5: =TEXT(DATE(Setup!$B$3,8,16),"ddd") | U5: =TEXT(DATE(Setup!$B$3,8,17),"ddd") | V5: =TEXT(DATE(Setup!$B$3,8,18),"ddd") | W5: =TEXT(DATE(Setup!$B$3,8,19),"ddd") | X5: =TEXT(DATE(Setup!$B$3,8,20),"ddd") | Y5: =TEXT(DATE(Setup!$B$3,8,21),"ddd") | Z5: =TEXT(DATE(Setup!$B$3,8,22),"ddd") | AA5: =TEXT(DATE(Setup!$B$3,8,23),"ddd") | AB5: =TEXT(DATE(Setup!$B$3,8,24),"ddd") | AC5: =TEXT(DATE(Setup!$B$3,8,25),"ddd") | AD5: =TEXT(DATE(Setup!$B$3,8,26),"ddd") | AE5: =TEXT(DATE(Setup!$B$3,8,27),"ddd") | AF5: =TEXT(DATE(Setup!$B$3,8,28),"ddd") | AG5: =TEXT(DATE(Setup!$B$3,8,29),"ddd") | AH5: =TEXT(DATE(Setup!$B$3,8,30),"ddd") | AI5: =TEXT(DATE(Setup!$B$3,8,31),"ddd")
A6: Active | B6: Habit | C6: Type | D6: Points | E6: 1 | F6: 2 | G6: 3 | H6: 4 | I6: 5 | J6: 6 | K6: 7 | L6: 8 | M6: 9 | N6: 10 | O6: 11 | P6: 12 | Q6: 13 | R6: 14 | S6: 15 | T6: 16 | U6: 17 | V6: 18 | W6: 19 | X6: 20 | Y6: 21 | Z6: 22 | AA6: 23 | AB6: 24 | AC6: 25 | AD6: 26 | AE6: 27 | AF6: 28 | AG6: 29 | AH6: 30 | AI6: 31 | AJ6: Total
A7: =Setup!D9 | B7: =Setup!A9 | C7: =Setup!B9 | D7: =Setup!E9 | AJ7: =IF($A7=1,SUMPRODUCT(($E$6:$AI$6<=$B$3)*(E7:AI7)),"")
A8: =Setup!D10 | B8: =Setup!A10 | C8: =Setup!B10 | D8: =Setup!E10 | AJ8: =IF($A8=1,SUMPRODUCT(($E$6:$AI$6<=$B$3)*(E8:AI8)),"")
A9: =Setup!D11 | B9: =Setup!A11 | C9: =Setup!B11 | D9: =Setup!E11 | AJ9: =IF($A9=1,SUMPRODUCT(($E$6:$AI$6<=$B$3)*(E9:AI9)),"")
A10: =Setup!D12 | B10: =Setup!A12 | C10: =Setup!B12 | D10: =Setup!E12 | AJ10: =IF($A10=1,SUMPRODUCT(($E$6:$AI$6<=$B$3)*(E10:AI10)),"")
A11: =Setup!D13 | B11: =Setup!A13 | C11: =Setup!B13 | D11: =Setup!E13 | AJ11: =IF($A11=1,SUMPRODUCT(($E$6:$AI$6<=$B$3)*(E11:AI11)),"")
A12: =Setup!D14 | B12: =Setup!A14 | C12: =Setup!B14 | D12: =Setup!E14 | AJ12: =IF($A12=1,SUMPRODUCT(($E$6:$AI$6<=$B$3)*(E12:AI12)),"")
A13: =Setup!D15 | B13: =Setup!A15 | C13: =Setup!B15 | D13: =Setup!E15 | AJ13: =IF($A13=1,SUMPRODUCT(($E$6:$AI$6<=$B$3)*(E13:AI13)),"")
A14: =Setup!D16 | B14: =Setup!A16 | C14: =Setup!B16 | D14: =Setup!E16 | AJ14: =IF($A14=1,SUMPRODUCT(($E$6:$AI$6<=$B$3)*(E14:AI14)),"")
A15: =Setup!D17 | B15: =Setup!A17 | C15: =Setup!B17 | D15: =Setup!E17 | AJ15: =IF($A15=1,SUMPRODUCT(($E$6:$AI$6<=$B$3)*(E15:AI15)),"")
A16: =Setup!D18 | B16: =Setup!A18 | C16: =Setup!B18 | D16: =Setup!E18 | AJ16: =IF($A16=1,SUMPRODUCT(($E$6:$AI$6<=$B$3)*(E16:AI16)),"")
A17: =Setup!D19 | B17: =Setup!A19 | C17: =Setup!B19 | D17: =Setup!E19 | AJ17: =IF($A17=1,SUMPRODUCT(($E$6:$AI$6<=$B$3)*(E17:AI17)),"")
A18: =Setup!D20 | B18: =Setup!A20 | C18: =Setup!B20 | D18: =Setup!E20 | AJ18: =IF($A18=1,SUMPRODUCT(($E$6:$AI$6<=$B$3)*(E18:AI18)),"")
... A26: =Setup!D28 | B26: =Setup!A28 | C26: =Setup!B28 | D26: =Setup!E28 | AJ26: =IF($A26=1,SUMPRODUCT(($E$6:$AI$6<=$B$3)*(E26:AI26)),"")
A29: Daily summary
A30: Good habits done | E30: =SUMPRODUCT(($A$7:$A$26=1)*($C$7:$C$26="Good")*(E7:E26)) | F30: =SUMPRODUCT(($A$7:$A$26=1)*($C$7:$C$26="Good")*(F7:F26)) | G30: =SUMPRODUCT(($A$7:$A$26=1)*($C$7:$C$26="Good")*(G7:G26)) | H30: =SUMPRODUCT(($A$7:$A$26=1)*($C$7:$C$26="Good")*(H7:H26)) | I30: =SUMPRODUCT(($A$7:$A$26=1)*($C$7:$C$26="Good")*(I7:I26)) | J30: =SUMPRODUCT(($A$7:$A$26=1)*($C$7:$C$26="Good")*(J7:J26)) | K30: =SUMPRODUCT(($A$7:$A$26=1)*($C$7:$C$26="Good")*(K7:K26)) | L30: =SUMPRODUCT(($A$7:$A$26=1)*($C$7:$C$26="Good")*(L7:L26)) | ... AI30: =SUMPRODUCT(($A$7:$A$26=1)*($C$7:$C$26="Good")*(AI7:AI26)) | AL30: Monthly totals
A31: Bad habits happened | E31: =SUMPRODUCT(($A$7:$A$26=1)*($C$7:$C$26="Bad")*(E7:E26)) | F31: =SUMPRODUCT(($A$7:$A$26=1)*($C$7:$C$26="Bad")*(F7:F26)) | G31: =SUMPRODUCT(($A$7:$A$26=1)*($C$7:$C$26="Bad")*(G7:G26)) | H31: =SUMPRODUCT(($A$7:$A$26=1)*($C$7:$C$26="Bad")*(H7:H26)) | I31: =SUMPRODUCT(($A$7:$A$26=1)*($C$7:$C$26="Bad")*(I7:I26)) | J31: =SUMPRODUCT(($A$7:$A$26=1)*($C$7:$C$26="Bad")*(J7:J26)) | K31: =SUMPRODUCT(($A$7:$A$26=1)*($C$7:$C$26="Bad")*(K7:K26)) | L31: =SUMPRODUCT(($A$7:$A$26=1)*($C$7:$C$26="Bad")*(L7:L26)) | ... AI31: =SUMPRODUCT(($A$7:$A$26=1)*($C$7:$C$26="Bad")*(AI7:AI26)) | AL31: Good done | AM31: =SUMPRODUCT(($E$6:$AI$6<=$B$3)*(E30:AI30))
A32: Net score | E32: =SUMPRODUCT(($A$7:$A$26=1)*($D$7:$D$26)*(E7:E26)) | F32: =SUMPRODUCT(($A$7:$A$26=1)*($D$7:$D$26)*(F7:F26)) | G32: =SUMPRODUCT(($A$7:$A$26=1)*($D$7:$D$26)*(G7:G26)) | H32: =SUMPRODUCT(($A$7:$A$26=1)*($D$7:$D$26)*(H7:H26)) | I32: =SUMPRODUCT(($A$7:$A$26=1)*($D$7:$D$26)*(I7:I26)) | J32: =SUMPRODUCT(($A$7:$A$26=1)*($D$7:$D$26)*(J7:J26)) | K32: =SUMPRODUCT(($A$7:$A$26=1)*($D$7:$D$26)*(K7:K26)) | L32: =SUMPRODUCT(($A$7:$A$26=1)*($D$7:$D$26)*(L7:L26)) | ... AI32: =SUMPRODUCT(($A$7:$A$26=1)*($D$7:$D$26)*(AI7:AI26)) | AL32: Bad happened | AM32: =SUMPRODUCT(($E$6:$AI$6<=$B$3)*(E31:AI31))
